<!--URDF MODEL 48 DoFs-->

<robot name="XSensStyleModel_template">
<!--To open this model with Gazebo replace the null masses, inertias and dimensions of the 'fake links f1 and f2'-->
    <!--LINKS-->
	<!--Link base (1)-->
	<link name="Pelvis">
        <inertial>
            <mass value="5.816"/>
			<!--COM origin wrt pHipOrigin-->
            <origin xyz="0           0    0.056125" rpy="0 0 0" />
            <inertia ixx="0.04582" iyy="0.017636" izz="0.05243" ixy="0" ixz="0" iyz="0"/>
        </inertial>

        <visual>
			<!--box origin wrt pHipOrigin-->
            <origin xyz="0           0    0.056125" rpy="0 0 0" />
            <geometry>
                <box size="0.15816     0.28838     0.10665"/>
            </geometry>
        </visual>

        <collision>
			<!--box origin wrt pHipOrigin-->
            <origin xyz="0           0    0.056125" rpy="0 0 0" />
            <geometry>
                <box size="0.15816     0.28838     0.10665"/>
            </geometry>
        </collision>

    </link>
    <!--Chain from (2) to (7)-->
	<link name="L5_f1">
        <inertial>
            <mass value="0"/>
            <origin xyz="0 0 0" rpy="0 0 0" />
            <inertia ixx="0" iyy="0" izz="0" ixy="0" ixz="0" iyz="0"/>
        </inertial>
    </link>
	<link name="L5">
        <inertial>
            <mass value="7.4154"/>
			<!--COM origin wrt jL5S1-->
            <origin xyz="0           0    0.046982" rpy="0 0 0" />
            <inertia ixx="0.027034" iyy="0.020913" izz="0.037036" ixy="0" ixz="0" iyz="0"/>
        </inertial>

        <visual>
			<!--box origin origin wrt jL5S1-->
            <origin xyz="0           0    0.046982" rpy="0 0 0" />
            <geometry>
                <box size="0.15816     0.18687    0.093964"/>
            </geometry>
        </visual>

        <collision>
			<!--box origin origin wrt jL5S1-->
            <origin xyz="0           0    0.046982" rpy="0 0 0" />
            <geometry>
                <box size="0.15816     0.18687    0.093964"/>
            </geometry>
        </collision>
    </link>
	<link name="L3_f1">
        <inertial>
            <mass value="0"/>
            <origin xyz="0 0 0" rpy="0 0 0" />
            <inertia ixx="0" iyy="0" izz="0" ixy="0" ixz="0" iyz="0"/>
        </inertial>
    </link>
	<link name="L3">
        <inertial>
            <mass value="7.4154"/>
			<!--COM origin wrt jL4L3-->
            <origin xyz="0           0    0.042435" rpy="0 0 0" />
            <inertia ixx="0.026029" iyy="0.019908" izz="0.037036" ixy="0" ixz="0" iyz="0"/>
        </inertial>

        <visual>
			<!--box origin origin wrt jL4L3-->
            <origin xyz="0           0    0.042435" rpy="0 0 0" />
            <geometry>
                <box size="0.15816     0.18687     0.08487"/>
            </geometry>
        </visual>

        <collision>
			<!--box origin origin wrt jL4L3-->
            <origin xyz="0           0    0.042435" rpy="0 0 0" />
            <geometry>
                <box size="0.15816     0.18687     0.08487"/>
            </geometry>
        </collision>
    </link>
	<link name="T12_f1">
        <inertial>
            <mass value="0"/>
            <origin xyz="0 0 0" rpy="0 0 0" />
            <inertia ixx="0" iyy="0" izz="0" ixy="0" ixz="0" iyz="0"/>
        </inertial>
    </link>
	<link name="T12">
        <inertial>
            <mass value="7.4154"/>
			<!--COM origin wrt jL1T12-->
            <origin xyz="0           0    0.042435" rpy="0 0 0" />
            <inertia ixx="0.026029" iyy="0.019908" izz="0.037036" ixy="0" ixz="0" iyz="0"/>
        </inertial>

        <visual>
			<!--box origin origin wrt jL1T12-->
            <origin xyz="0           0    0.042435" rpy="0 0 0" />
            <geometry>
                <box size="0.15816     0.18687     0.08487"/>
            </geometry>
        </visual>

        <collision>
			<!--box origin origin wrt jL1T12-->
            <origin xyz="0           0    0.042435" rpy="0 0 0" />
            <geometry>
                <box size="0.15816     0.18687     0.08487"/>
            </geometry>
        </collision>
    </link>
	<link name="T8_f1">
        <inertial>
            <mass value="0"/>
            <origin xyz="0 0 0" rpy="0 0 0" />
            <inertia ixx="0" iyy="0" izz="0" ixy="0" ixz="0" iyz="0"/>
        </inertial>
    </link>
	<link name="T8_f2">
        <inertial>
            <mass value="0"/>
            <origin xyz="0 0 0" rpy="0 0 0" />
            <inertia ixx="0" iyy="0" izz="0" ixy="0" ixz="0" iyz="0"/>
        </inertial>
    </link>
	<link name="T8">
        <inertial>
            <mass value="2.908"/>
			<!--COM origin wrt jT9T8-->
            <origin xyz="0           0    0.059789" rpy="0 0 0" />
            <inertia ixx="0.0042999" iyy="0.0083658" izz="0.0057357" ixy="0" ixz="0" iyz="0"/>
        </inertial>

        <visual>
			<!--box origin wrt jT9T8-->
            <origin xyz="0           0    0.059789" rpy="0 0 0" />
            <geometry>
                <box size="0.14221    0.058696     0.11958"/>
            </geometry>
        </visual>

        <collision>
			<!--box origin wrt jT9T8-->
            <origin xyz="0           0    0.059789" rpy="0 0 0" />
            <geometry>
                <box size="0.14221    0.058696     0.11958"/>
            </geometry>
        </collision>

    </link>
	<link name="Neck_f1">
        <inertial>
            <mass value="0"/>
            <origin xyz="0 0 0" rpy="0 0 0" />
            <inertia ixx="0" iyy="0" izz="0" ixy="0" ixz="0" iyz="0"/>
        </inertial>
    </link>
	<link name="Neck_f2">
        <inertial>
            <mass value="0"/>
            <origin xyz="0 0 0" rpy="0 0 0" />
            <inertia ixx="0" iyy="0" izz="0" ixy="0" ixz="0" iyz="0"/>
        </inertial>
    </link>
	<link name="Neck">
        <inertial>
            <mass value="0.8724"/>
			<!--COM origin wrt jT1C7-->
            <origin xyz="0           0    0.048835" rpy="0 0 0" />
            <inertia ixx="0.00091024" iyy="0.00091024" izz="0.00043345" ixy="0" ixz="0" iyz="0"/>
        </inertial>

        <visual>
			<!--box origin wrt jT1C7-->
            <origin xyz="0           0    0.048835" rpy="0 0 0" />
            <geometry>
		<cylinder length="0.09767" radius="0.015762"/>
            </geometry>
        </visual>

        <collision>
			<!--box origin wrt jT1C7-->
            <origin xyz="0           0    0.048835" rpy="0 0 0" />
            <geometry>
                <cylinder length="0.09767" radius="0.015762"/>
            </geometry>
        </collision>
    </link>
	<link name="Head_f1">
        <inertial>
            <mass value="0"/>
            <origin xyz="0 0 0" rpy="0 0 0" />
            <inertia ixx="0" iyy="0" izz="0" ixy="0" ixz="0" iyz="0"/>
        </inertial>
    </link>
	<link name="Head">
        <inertial>
            <mass value="2.6172"/>
			<!--COM origin wrt jC1Head-->
            <origin xyz="0           0    0.099558" rpy="0 0 0" />
            <inertia ixx="0.010376" iyy="0.010376" izz="0.010376" ixy="0" ixz="0" iyz="0"/>
        </inertial>

        <visual>
			<!--boc origin wrt jC1Head-->
            <origin xyz="0           0    0.099558" rpy="0 0 0" />
            <geometry>
                <sphere radius="0.099558"/>
            </geometry>
        </visual>

        <collision>
			<!--box origin wrt jC1Head-->
            <origin xyz="0           0    0.099558" rpy="0 0 0" />
            <geometry>
                <sphere radius="0.099558"/>
            </geometry>
        </collision>

    </link>
	<!--Chain from (8) to (11)-->
	<link name="RightShoulder">
        <inertial>
            <mass value="2.2537"/>
			<!--COM origin wrt jRightC7Shoulder-->
            <origin xyz="0   -0.078772           0" rpy="0 0 0" />
            <inertia ixx="0.0051014" iyy="0.00087992" izz="0.0051014" ixy="0" ixz="0" iyz="0"/>
        </inertial>

        <visual>
			<!--box origin wrt jRightC7Shoulder. RPY rotated of pi/2.-->
            <origin xyz="0   -0.078772           0" rpy="1.5708 0 0" />
            <geometry>
                <cylinder length="0.15754" radius="0.027944"/>
            </geometry>
        </visual>

        <collision>
			<!--box origin wrt jRightC7Shoulder. RPY rotated of pi/2.-->
            <origin xyz="0   -0.078772           0" rpy="1.5708 0 0" />
            <geometry>
                <cylinder length="0.15754" radius="0.027944"/>
            </geometry>
        </collision>

    </link>
	<link name="RightUpperArm_f1">
        <inertial>
            <mass value="0"/>
            <origin xyz="0 0 0" rpy="0 0 0" />
            <inertia ixx="0" iyy="0" izz="0" ixy="0" ixz="0" iyz="0"/>
        </inertial>
    </link>
	<link name="RightUpperArm_f2">
        <inertial>
            <mass value="0"/>
            <origin xyz="0 0 0" rpy="0 0 0" />
            <inertia ixx="0" iyy="0" izz="0" ixy="0" ixz="0" iyz="0"/>
        </inertial>
    </link>
    <link name="RightUpperArm">
        <inertial>
            <mass value="2.181"/>
			<!--COM origin wrt jRightShoulder-->
            <origin xyz="0    -0.16437           0" rpy="0 0 0" />
            <inertia ixx="0.020332" iyy="0.0013806" izz="0.020332" ixy="0" ixz="0" iyz="0"/>
        </inertial>

        <visual>
			<!--box origin wrt jRightShoulder. RPY rotated of pi/2.-->
            <origin xyz="0    -0.16437           0" rpy="1.5708 0 0" />
            <geometry>
                <cylinder length="0.32874" radius="0.035581"/>
            </geometry>
        </visual>

        <collision>
			<!--box origin wrt jRightShoulder. RPY rotated of pi/2.-->
            <origin xyz="0    -0.16437           0" rpy="1.5708 0 0" />
            <geometry>
                <cylinder length="0.32874" radius="0.035581"/>
            </geometry>
        </collision>

    </link>
	<link name="RightForeArm_f1">
        <inertial>
            <mass value="0"/>
            <origin xyz="0 0 0" rpy="0 0 0" />
            <inertia ixx="0" iyy="0" izz="0" ixy="0" ixz="0" iyz="0"/>
        </inertial>
    </link>
	<link name="RightForeArm">
        <inertial>
            <mass value="1.454"/>
			<!--COM origin wrt jRightElbow-->
            <origin xyz="0    -0.13431           0" rpy="0 0 0" />
            <inertia ixx="0.008948" iyy="0.00040906" izz="0.008948" ixy="0" ixz="0" iyz="0"/>
        </inertial>

        <visual>
			<!--box origin wrt jRightElbow. RPY rotated of pi/2.-->
            <origin xyz="0    -0.13431           0" rpy="1.5708 0 0" />
            <geometry>
                <cylinder length="0.26863" radius="0.023721"/>
            </geometry>
        </visual>

        <collision>
			<!--box origin wrt jRightElbow. RPY rotated of pi/2.-->
            <origin xyz="0    -0.13431           0" rpy="1.5708 0 0" />
            <geometry>
                <cylinder length="0.26863" radius="0.023721"/>
            </geometry>
        </collision>

    </link>
	<link name="RightHand_f1">
        <inertial>
            <mass value="0"/>
            <origin xyz="0 0 0" rpy="0 0 0" />
            <inertia ixx="0" iyy="0" izz="0" ixy="0" ixz="0" iyz="0"/>
        </inertial>
    </link>
	<link name="RightHand">
        <inertial>
            <mass value="0.4362"/>
			<!--COM origin wrt jRightWrist-->
            <origin xyz="0    -0.10039           0" rpy="0 0 0" />
            <inertia ixx="0.0015471" iyy="0.00073303" izz="0.0021165" ixy="0" ixz="0" iyz="0"/>
        </inertial>

        <visual>
			<!--box origin wrt jRightWrist-->
            <origin xyz="0    -0.10039           0" rpy="0 0 0" />
            <geometry>
                <box size="0.13385     0.20077    0.047441"/>
            </geometry>
        </visual>

        <collision>
			<!--box origin wrt jRightWrist-->
            <origin xyz="0    -0.10039           0" rpy="0 0 0" />
            <geometry>
                <box size="0.13385     0.20077    0.047441"/>
            </geometry>
        </collision>

    </link>
	<!--Chain from (12) to (15)-->
	<link name="LeftShoulder">
        <inertial>
            <mass value="2.2537"/>
			<!--COM origin wrt jLeftC7Shoulder-->
            <origin xyz="0    0.078772           0" rpy="0 0 0" />
            <inertia ixx="0.0051014" iyy="0.00087992" izz="0.0051014" ixy="0" ixz="0" iyz="0"/>
        </inertial>

        <visual>
			<!--box origin wrt jLeftC7Shoulder. RPY rotated of pi/2.-->
            <origin xyz="0    0.078772           0" rpy="1.5708 0 0" />
            <geometry>
                <cylinder length="0.15754" radius="0.027944"/>
            </geometry>
        </visual>

        <collision>
			<!--box origin wrt jLeftC7Shoulder. RPY rotated of pi/2.-->
            <origin xyz="0    0.078772           0" rpy="1.5708 0 0" />
            <geometry>
                <cylinder length="0.15754" radius="0.027944"/>
            </geometry>
        </collision>

    </link>
	<link name="LeftUpperArm_f1">
        <inertial>
            <mass value="0"/>
            <origin xyz="0 0 0" rpy="0 0 0" />
            <inertia ixx="0" iyy="0" izz="0" ixy="0" ixz="0" iyz="0"/>
        </inertial>
    </link>
	<link name="LeftUpperArm_f2">
        <inertial>
            <mass value="0"/>
            <origin xyz="0 0 0" rpy="0 0 0" />
            <inertia ixx="0" iyy="0" izz="0" ixy="0" ixz="0" iyz="0"/>
        </inertial>
    </link>
	<link name="LeftUpperArm">
        <inertial>
            <mass value="2.181"/>
			<!--COM origin wrt jLeftShoulder-->
            <origin xyz="0     0.16437           0" rpy="0 0 0" />
            <inertia ixx="0.020332" iyy="0.0013806" izz="0.020332" ixy="0" ixz="0" iyz="0"/>
        </inertial>

        <visual>
			<!--box origin wrt jLeftShoulder. RPY rotated of pi/2.-->
            <origin xyz="0     0.16437           0" rpy="1.5708 0 0" />
            <geometry>
                <cylinder length="0.32874" radius="0.035581"/>
            </geometry>
        </visual>

        <collision>
			<!--box origin wrt jLeftShoulder. RPY rotated of pi/2.-->
            <origin xyz="0     0.16437           0" rpy="1.5708 0 0" />
            <geometry>
                <cylinder length="0.32874" radius="0.035581"/>
            </geometry>
        </collision>

    </link>
	<link name="LeftForeArm_f1">
        <inertial>
            <mass value="0"/>
            <origin xyz="0 0 0" rpy="0 0 0" />
            <inertia ixx="0" iyy="0" izz="0" ixy="0" ixz="0" iyz="0"/>
        </inertial>
    </link>
	<link name="LeftForeArm">
        <inertial>
            <mass value="1.454"/>
			<!--COM origin wrt jLeftElbow-->
            <origin xyz="0     0.13431           0" rpy="0 0 0" />
            <inertia ixx="0.008948" iyy="0.00040906" izz="0.008948" ixy="0" ixz="0" iyz="0"/>
        </inertial>

        <visual>
			<!--box origin wrt jLeftElbow. RPY rotated of pi/2.-->
            <origin xyz="0     0.13431           0" rpy="1.5708 0 0" />
            <geometry>
                <cylinder length="0.26863" radius="0.023721"/>
            </geometry>
        </visual>

        <collision>
			<!--box origin wrt jLeftElbow. RPY rotated of pi/2.-->
            <origin xyz="0     0.13431           0" rpy="1.5708 0 0" />
            <geometry>
                <cylinder length="0.26863" radius="0.023721"/>
            </geometry>
        </collision>

    </link>
	<link name="LeftHand_f1">
        <inertial>
            <mass value="0"/>
            <origin xyz="0 0 0" rpy="0 0 0" />
            <inertia ixx="0" iyy="0" izz="0" ixy="0" ixz="0" iyz="0"/>
        </inertial>
    </link>
	<link name="LeftHand">
        <inertial>
            <mass value="0.4362"/>
			<!--COM origin wrt jLeftWrist-->
            <origin xyz="0     0.10039           0" rpy="0 0 0" />
            <inertia ixx="0.0015471" iyy="0.00073303" izz="0.0021165" ixy="0" ixz="0" iyz="0"/>
        </inertial>

        <visual>
			<!--COM origin wrt jLeftWrist-->
            <origin xyz="0     0.10039           0" rpy="0 0 0" />
            <geometry>
                <box size="0.13385     0.20077    0.047441"/>
            </geometry>
        </visual>

        <collision>
			<!--COM origin wrt jLeftWrist-->
            <origin xyz="0     0.10039           0" rpy="0 0 0" />
            <geometry>
                <box size="0.13385     0.20077    0.047441"/>
            </geometry>
        </collision>

    </link>
	<!--Chain from (16) to (19)-->
	<link name="RightUpperLeg_f1">
        <inertial>
            <mass value="0"/>
            <origin xyz="0 0 0" rpy="0 0 0" />
            <inertia ixx="0" iyy="0" izz="0" ixy="0" ixz="0" iyz="0"/>
        </inertial>
    </link>
	<link name="RightUpperLeg_f2">
        <inertial>
            <mass value="0"/>
            <origin xyz="0 0 0" rpy="0 0 0" />
            <inertia ixx="0" iyy="0" izz="0" ixy="0" ixz="0" iyz="0"/>
        </inertial>
    </link>
    <link name="RightUpperLeg">
        <inertial>
            <mass value="9.0875"/>
			<!--COM origin wrt jRightHip-->
            <origin xyz="0           0     -0.2408" rpy="0 0 0" />
            <inertia ixx="0.18406" iyy="0.18406" izz="0.016841" ixy="0" ixz="0" iyz="0"/>
        </inertial>

        <visual>
			<!--box origin wrt jRightHip-->
            <origin xyz="0           0     -0.2408" rpy="0 0 0" />
            <geometry>
                <cylinder length="0.48159" radius="0.060881"/>
            </geometry>
        </visual>

        <collision>
			<!--box origin wrt jRightHip-->
            <origin xyz="0           0     -0.2408" rpy="0 0 0" />
            <geometry>
                <cylinder length="0.48159" radius="0.060881"/>
            </geometry>
        </collision>

    </link>
	<link name="RightLowerLeg_f1">
        <inertial>
            <mass value="0"/>
            <origin xyz="0 0 0" rpy="0 0 0" />
            <inertia ixx="0" iyy="0" izz="0" ixy="0" ixz="0" iyz="0"/>
        </inertial>
    </link>
    <link name="RightLowerLeg">
        <inertial>
            <mass value="2.6536"/>
			<!--COM origin wrt jRightKnee-->
            <origin xyz="0           0    -0.23981" rpy="0 0 0" />
            <inertia ixx="0.052154" iyy="0.052154" izz="0.0025724" ixy="0" ixz="0" iyz="0"/>
        </inertial>

        <visual>
			<!--box origin wrt jRightKnee-->
            <origin xyz="0           0    -0.23981" rpy="0 0 0" />
            <geometry>
                <cylinder length="0.47962" radius="0.044033"/>
            </geometry>
        </visual>

        <collision>
			<!--box origin wrt jRightKnee-->
            <origin xyz="0           0    -0.23981" rpy="0 0 0" />
            <geometry>
                <cylinder length="0.47962" radius="0.044033"/>
            </geometry>
        </collision>

    </link>
	<link name="RightFoot_f1">
        <inertial>
            <mass value="0"/>
            <origin xyz="0 0 0" rpy="0 0 0" />
            <inertia ixx="0" iyy="0" izz="0" ixy="0" ixz="0" iyz="0"/>
        </inertial>
    </link>
	<link name="RightFoot_f2">
        <inertial>
            <mass value="0"/>
            <origin xyz="0 0 0" rpy="0 0 0" />
            <inertia ixx="0" iyy="0" izz="0" ixy="0" ixz="0" iyz="0"/>
        </inertial>
    </link>
    <link name="RightFoot">
        <inertial>
            <mass value="0.9451"/>
			<!--COM origin wrt jRightAnkle-->
            <origin xyz="0.05699           0   -0.038957" rpy="0 0 0" />
            <inertia ixx="0.0010889" iyy="0.0032762" izz="0.0034089" ixy="0" ixz="0" iyz="0"/>
        </inertial>

        <visual>
			<!--box origin wrt jRightAnkle-->
	    	<origin xyz="0.05699           0   -0.038957" rpy="0 0 0" />
            <geometry>
                <box size="0.18849    0.088065    0.077914"/>
            </geometry>
        </visual>

        <collision>
			<!--box origin wrt jRightAnkle-->
		    <origin xyz="0.05699           0   -0.038957" rpy="0 0 0" />
	            <geometry>
	                <box size="0.18849    0.088065    0.077914"/>
	            </geometry>
        </collision>

    </link>
    <link name="RightToe">
        <inertial>
            <mass value="0.10905"/>
			<!--COM origin wrt jRightBallFoot-->
            <origin xyz="0.035756           0           0" rpy="0 0 0" />
            <inertia ixx="7.299e-05" iyy="4.8986e-05" izz="0.00011695" ixy="0" ixz="0" iyz="0"/>
        </inertial>

        <visual>
			<!--box origin wrt jRightBallFoot-->
            <origin xyz="0.035756           0           0" rpy="0 0 0" />
            <geometry>
                <box size="0.071513    0.088065    0.016626"/>
            </geometry>
        </visual>

        <collision>
			<!--box origin wrt jRightBallFoot-->
            <origin xyz="0.035756           0           0" rpy="0 0 0" />
            <geometry>
                <box size="0.071513    0.088065    0.016626"/>
            </geometry>
        </collision>
    </link>
	<!--Chain from (20) to (23)-->
	<link name="LeftUpperLeg_f1">
        <inertial>
            <mass value="0"/>
            <origin xyz="0 0 0" rpy="0 0 0" />
            <inertia ixx="0" iyy="0" izz="0" ixy="0" ixz="0" iyz="0"/>
        </inertial>
    </link>
	<link name="LeftUpperLeg_f2">
        <inertial>
            <mass value="0"/>
            <origin xyz="0 0 0" rpy="0 0 0" />
            <inertia ixx="0" iyy="0" izz="0" ixy="0" ixz="0" iyz="0"/>
        </inertial>
    </link>
    <link name="LeftUpperLeg">
        <inertial>
            <mass value="9.0875"/>
			<!--COM origin wrt jLeftHip-->
            <origin xyz="0           0     -0.2408" rpy="0 0 0" />
            <inertia ixx="0.18406" iyy="0.18406" izz="0.016841" ixy="0" ixz="0" iyz="0"/>
        </inertial>

        <visual>
			<!--box origin wrt jLeftHip-->
            <origin xyz="0           0     -0.2408" rpy="0 0 0" />
            <geometry>
                <cylinder length="0.48159" radius="0.060881"/>
            </geometry>
        </visual>

        <collision>
			<!--box origin wrt jLeftHip-->
            <origin xyz="0           0     -0.2408" rpy="0 0 0" />
            <geometry>
                <cylinder length="0.48159" radius="0.060881"/>
            </geometry>
        </collision>

    </link>
	<link name="LeftLowerLeg_f1">
        <inertial>
            <mass value="0"/>
            <origin xyz="0 0 0" rpy="0 0 0" />
            <inertia ixx="0" iyy="0" izz="0" ixy="0" ixz="0" iyz="0"/>
        </inertial>
    </link>
	<link name="LeftLowerLeg">
        <inertial>
            <mass value="2.6536"/>
			<!--COM origin wrt jLeftKnee-->
            <origin xyz="0           0    -0.23981" rpy="0 0 0" />
            <inertia ixx="0.052154" iyy="0.052154" izz="0.0025724" ixy="0" ixz="0" iyz="0"/>
        </inertial>

        <visual>
			<!--box origin wrt jLeftKnee-->
            <origin xyz="0           0    -0.23981" rpy="0 0 0" />
            <geometry>
		<cylinder length="0.47962" radius="0.044033"/>
            </geometry>
        </visual>

        <collision>
			<!--box origin wrt jLeftKnee-->
            <origin xyz="0           0    -0.23981" rpy="0 0 0" />
            <geometry>
		<cylinder length="0.47962" radius="0.044033"/>
            </geometry>
        </collision>

    </link>
	<link name="LeftFoot_f1">
        <inertial>
            <mass value="0"/>
            <origin xyz="0 0 0" rpy="0 0 0" />
            <inertia ixx="0" iyy="0" izz="0" ixy="0" ixz="0" iyz="0"/>
        </inertial>
    </link>
	<link name="LeftFoot_f2">
        <inertial>
            <mass value="0"/>
            <origin xyz="0 0 0" rpy="0 0 0" />
            <inertia ixx="0" iyy="0" izz="0" ixy="0" ixz="0" iyz="0"/>
        </inertial>
    </link>
    <link name="LeftFoot">
        <inertial>
            <mass value="0.9451"/>
			<!--COM origin wrt jLeftAnkle-->
            <origin xyz="0.05699           0   -0.038957" rpy="0 0 0" />
            <inertia ixx="0.0010889" iyy="0.0032762" izz="0.0034089" ixy="0" ixz="0" iyz="0"/>
        </inertial>

        <visual>
			<!--box origin wrt jLeftAnkle-->
	   	 	<origin xyz="0.05699           0   -0.038957" rpy="0 0 0" />
            <geometry>
                <box size="0.18849    0.088065    0.077914"/>
            </geometry>
        </visual>

        <collision>
			<!--box origin wrt jLeftAnkle-->
		    <origin xyz="0.05699           0   -0.038957" rpy="0 0 0" />
	            <geometry>
	                <box size="0.18849    0.088065    0.077914"/>
	            </geometry>
        </collision>

    </link>
	<link name="LeftToe">
        <inertial>
            <mass value="0.10905"/>
			<!--COM origin wrt jLeftBallFoot-->
            <origin xyz="0.035756           0           0" rpy="0 0 0" />
            <inertia ixx="7.299e-05" iyy="4.8986e-05" izz="0.00011695" ixy="0" ixz="0" iyz="0"/>
        </inertial>

        <visual>
			<!--box origin wrt jLeftBallFoot-->
            <origin xyz="0.035756           0           0" rpy="0 0 0" />
            <geometry>
                <box size="0.071513    0.088065    0.016626"/>
            </geometry>
        </visual>

        <collision>
			<!--box origin wrt jLeftBallFoot-->
            <origin xyz="0.035756           0           0" rpy="0 0 0" />
            <geometry>
                <box size="0.071513    0.088065    0.016626"/>
            </geometry>
        </collision>
    </link>


	<!--JOINTS-->
	<!--Chain from (2) to (7)-->
	<joint name="jL5S1_rotx" type="revolute">
        <origin xyz="-0.000571           0     0.10945" rpy="0 0 0"/>
        <parent link="Pelvis"/>
        <child link="L5_f1"/>
        <dynamics damping="0.1" friction="0.0"/>
        <limit effort="30" velocity="1.0" lower="-0.610865" upper="0.610865" />
        <axis xyz="1 0 0" />
    </joint>
	<joint name="jL5S1_roty" type="revolute">
        <origin xyz="0 0 0" rpy="0 0 0"/>
        <parent link="L5_f1"/>
        <child link="L5"/>
        <dynamics damping="0.1" friction="0.0"/>
        <limit effort="30" velocity="1.0" lower="-0.523599" upper="1.309" />
        <axis xyz="0 1 0" />
    </joint>
	<joint name="jL4L3_rotx" type="revolute">
        <origin xyz="0.001038           0    0.093964" rpy="0 0 0"/>
        <parent link="L5"/>
        <child link="L3_f1"/>
        <dynamics damping="0.1" friction="0.0"/>
        <limit effort="30" velocity="1.0" lower="-0.610865" upper="0.610865" />
        <axis xyz="1 0 0" />
    </joint>
	<joint name="jL4L3_roty" type="revolute">
        <origin xyz="0 0 0" rpy="0 0 0"/>
        <parent link="L3_f1"/>
        <child link="L3"/>
        <dynamics damping="0.1" friction="0.0"/>
        <limit effort="30" velocity="1.0" lower="-0.523599" upper="1.309" />
        <axis xyz="0 1 0" />
    </joint>
	<joint name="jL1T12_rotx" type="revolute">
        <origin xyz="0           0     0.08487" rpy="0 0 0"/>
        <parent link="L3"/>
        <child link="T12_f1"/>
        <dynamics damping="0.1" friction="0.0"/>
        <limit effort="30" velocity="1.0" lower="-0.610865" upper="0.610865" />
        <axis xyz="1 0 0" />
    </joint>
	<joint name="jL1T12_roty" type="revolute">
        <origin xyz="0 0 0" rpy="0 0 0"/>
        <parent link="T12_f1"/>
        <child link="T12"/>
        <dynamics damping="0.1" friction="0.0"/>
        <limit effort="30" velocity="1.0" lower="-0.523599" upper="1.309" />
        <axis xyz="0 1 0" />
    </joint>
	<joint name="jT9T8_rotx" type="revolute">
        <origin xyz="0           0     0.08487" rpy="0 0 0"/>
        <parent link="T12"/>
        <child link="T8_f1"/>
        <dynamics damping="0.1" friction="0.0"/>
        <limit effort="30" velocity="1.0" lower="-0.349066" upper="0.349066" />
        <axis xyz="1 0 0" />
    </joint>
	<joint name="jT9T8_roty" type="revolute">
        <origin xyz="0 0 0" rpy="0 0 0"/>
        <parent link="T8_f1"/>
        <child link="T8_f2"/>
        <dynamics damping="0.1" friction="0.0"/>
        <limit effort="30" velocity="1.0" lower="-0.261799" upper="0.698132" />
        <axis xyz="0 1 0" />
    </joint>
    <joint name="jT9T8_rotz" type="revolute">
        <origin xyz="0 0 0" rpy="0 0 0"/>
        <parent link="T8_f2"/>
        <child link="T8"/>
        <dynamics damping="0.1" friction="0.0"/>
        <limit effort="30" velocity="1.0" lower="-0.610865" upper="0.610865" />
        <axis xyz="0 0 1" />
    </joint>
	<joint name="jT1C7_rotx" type="revolute">
        <origin xyz="0           0     0.11958" rpy="0 0 0"/>
        <parent link="T8"/>
        <child link="Neck_f1"/>
        <dynamics damping="0.1" friction="0.0"/>
        <limit effort="30" velocity="1.0" lower="-0.610865" upper="0.610865" />
        <axis xyz="1 0 0" />
    </joint>
	<joint name="jT1C7_roty" type="revolute">
        <origin xyz="0 0 0" rpy="0 0 0"/>
        <parent link="Neck_f1"/>
        <child link="Neck_f2"/>
        <dynamics damping="0.1" friction="0.0"/>
        <limit effort="30" velocity="1.0" lower="-0.959931" upper="1.5708" />
        <axis xyz="0 1 0" />
    </joint>
    <joint name="jT1C7_rotz" type="revolute">
        <origin xyz="0 0 0" rpy="0 0 0"/>
        <parent link="Neck_f2"/>
        <child link="Neck"/>
        <dynamics damping="0.1" friction="0.0"/>
        <limit effort="30" velocity="1.0" lower="-1.22173" upper="1.22173" />
        <axis xyz="0 0 1" />
    </joint>
	<joint name="jC1Head_rotx" type="revolute">
        <origin xyz="0.000993           0     0.09767" rpy="0 0 0"/>
        <parent link="Neck"/>
        <child link="Head_f1"/>
        <dynamics damping="0.1" friction="0.0"/>
        <limit effort="30" velocity="1.0" lower="-0.610865" upper="0.610865" />
        <axis xyz="1 0 0" />
    </joint>
	<joint name="jC1Head_roty" type="revolute">
        <origin xyz="0 0 0" rpy="0 0 0"/>
        <parent link="Head_f1"/>
        <child link="Head"/>
        <dynamics damping="0.1" friction="0.0"/>
        <limit effort="30" velocity="1.0" lower="-0.436332" upper="0.174533" />
        <axis xyz="0 1 0" />
    </joint>
	<!--Chain from (8) to (11)-->
	<joint name="jRightC7Shoulder_rotx" type="revolute">
        <origin xyz="0   -0.029348    0.067373" rpy="0 0 0"/>
        <parent link="T8"/>
        <child link="RightShoulder"/>
        <dynamics damping="0.1" friction="0.0"/>
        <limit effort="30" velocity="1.0" lower="-0.785398" upper="0.0872665" />
        <axis xyz="1 0 0" />
    </joint>
	<joint name="jRightShoulder_rotx" type="revolute">
        <origin xyz="0    -0.15754           0" rpy="0 0 0"/>
        <parent link="RightShoulder"/>
        <child link="RightUpperArm_f1"/>
        <dynamics damping="0.1" friction="0.0"/>
        <limit effort="30" velocity="1.0" lower="-2.35619" upper="1.5708" />
        <axis xyz="1 0 0" />
    </joint>
	<joint name="jRightShoulder_roty" type="revolute">
        <origin xyz="0 0 0" rpy="0 0 0"/>
        <parent link="RightUpperArm_f1"/>
        <child link="RightUpperArm_f2"/>
        <dynamics damping="0.1" friction="0.0"/>
        <limit effort="30" velocity="1.0" lower="-1.5708" upper="1.5708" />
        <axis xyz="0 1 0" />
    </joint>
    <joint name="jRightShoulder_rotz" type="revolute">
        <origin xyz="0 0 0" rpy="0 0 0"/>
        <parent link="RightUpperArm_f2"/>
        <child link="RightUpperArm"/>
        <dynamics damping="0.1" friction="0.0"/>
        <limit effort="30" velocity="1.0" lower="-0.785398" upper="3.14159" />
        <axis xyz="0 0 1" />
    </joint>
	<joint name="jRightElbow_roty" type="revolute">
        <origin xyz="0    -0.32874           0" rpy="0 0 0"/>
        <parent link="RightUpperArm"/>
        <child link="RightForeArm_f1"/>
        <dynamics damping="0.1" friction="0.0"/>
        <limit effort="30" velocity="1.0" lower="-1.5708" upper="1.48353" />
        <axis xyz="0 1 0" />
    </joint>
	<joint name="jRightElbow_rotz" type="revolute">
        <origin xyz="0 0 0" rpy="0 0 0"/>
        <parent link="RightForeArm_f1"/>
        <child link="RightForeArm"/>
        <dynamics damping="0.1" friction="0.0"/>
        <limit effort="30" velocity="1.0" lower="0" upper="2.53073" />
        <axis xyz="0 0 1" />
    </joint>
	<joint name="jRightWrist_rotx" type="revolute">
        <origin xyz="-1.2e-05    -0.26863           0" rpy="0 0 0"/>
        <parent link="RightForeArm"/>
        <child link="RightHand_f1"/>
        <dynamics damping="0.1" friction="0.0"/>
        <limit effort="30" velocity="1.0" lower="-0.872665" upper="1.0472" />
        <axis xyz="1 0 0" />
    </joint>
	<joint name="jRightWrist_rotz" type="revolute">
        <origin xyz="0 0 0" rpy="0 0 0"/>
        <parent link="RightHand_f1"/>
        <child link="RightHand"/>
        <dynamics damping="0.1" friction="0.0"/>
        <limit effort="30" velocity="1.0" lower="-0.523599" upper="0.349066" />
        <axis xyz="0 0 1" />
    </joint>
	<!--Chain from (12) to (15)-->
	<joint name="jLeftC7Shoulder_rotx" type="revolute">
        <origin xyz="0    0.029348    0.067373" rpy="0 0 0"/>
        <parent link="T8"/>
        <child link="LeftShoulder"/>
        <dynamics damping="0.1" friction="0.0"/>
        <limit effort="30" velocity="1.0" lower="-0.0872665" upper="0.785398" />
        <axis xyz="1 0 0" />
    </joint>
	<joint name="jLeftShoulder_rotx" type="revolute">
        <origin xyz="0     0.15754           0" rpy="0 0 0"/>
        <parent link="LeftShoulder"/>
        <child link="LeftUpperArm_f1"/>
        <dynamics damping="0.1" friction="0.0"/>
        <limit effort="30" velocity="1.0" lower="-1.5708" upper="2.35619" />
        <axis xyz="1 0 0" />
    </joint>
	<joint name="jLeftShoulder_roty" type="revolute">
        <origin xyz="0 0 0" rpy="0 0 0"/>
        <parent link="LeftUpperArm_f1"/>
        <child link="LeftUpperArm_f2"/>
        <dynamics damping="0.1" friction="0.0"/>
        <limit effort="30" velocity="1.0" lower="-1.5708" upper="1.5708" />
        <axis xyz="0 1 0" />
    </joint>
    <joint name="jLeftShoulder_rotz" type="revolute">
        <origin xyz="0 0 0" rpy="0 0 0"/>
        <parent link="LeftUpperArm_f2"/>
        <child link="LeftUpperArm"/>
        <dynamics damping="0.1" friction="0.0"/>
        <limit effort="30" velocity="1.0" lower="-3.14159" upper="0.785398" />
        <axis xyz="0 0 1" />
    </joint>
    <joint name="jLeftElbow_roty" type="revolute">
        <origin xyz="0     0.32874           0" rpy="0 0 0"/>
        <parent link="LeftUpperArm"/>
        <child link="LeftForeArm_f1"/>
        <dynamics damping="0.1" friction="0.0"/>
        <limit effort="30" velocity="1.0" lower="-1.5708" upper="1.48353" />
        <axis xyz="0 1 0" />
    </joint>
    <joint name="jLeftElbow_rotz" type="revolute">
        <origin xyz="0 0 0" rpy="0 0 0"/>
        <parent link="LeftForeArm_f1"/>
        <child link="LeftForeArm"/>
        <dynamics damping="0.1" friction="0.0"/>
        <limit effort="30" velocity="1.0" lower="-2.53073" upper="0" />
        <axis xyz="0 0 1" />
    </joint>
	<joint name="jLeftWrist_rotx" type="revolute">
        <origin xyz="-1.2e-05     0.26863           0" rpy="0 0 0"/>
        <parent link="LeftForeArm"/>
        <child link="LeftHand_f1"/>
        <dynamics damping="0.1" friction="0.0"/>
        <limit effort="30" velocity="1.0" lower="-1.0472" upper="0.872665" />
        <axis xyz="1 0 0" />
    </joint>
	<joint name="jLeftWrist_rotz" type="revolute">
        <origin xyz="0 0 0" rpy="0 0 0"/>
        <parent link="LeftHand_f1"/>
        <child link="LeftHand"/>
        <dynamics damping="0.1" friction="0.0"/>
        <limit effort="30" velocity="1.0" lower="-0.349066" upper="0.523599" />
        <axis xyz="0 0 1" />
    </joint>
	<!--Chain from (16) to (19)-->
	<joint name="jRightHip_rotx" type="revolute">
        <origin xyz="0.000286   -0.093433    0.002799" rpy="0 0 0"/>
        <parent link="Pelvis"/>
        <child link="RightUpperLeg_f1"/>
        <dynamics damping="0.1" friction="0.0"/>
        <limit effort="30" velocity="1.0" lower="-0.785398" upper="0.523599" />
        <axis xyz="1 0 0" />
    </joint>
	<joint name="jRightHip_roty" type="revolute">
        <origin xyz="0 0 0" rpy="0 0 0"/>
        <parent link="RightUpperLeg_f1"/>
        <child link="RightUpperLeg_f2"/>
        <dynamics damping="0.1" friction="0.0"/>
        <limit effort="30" velocity="1.0" lower="-0.261799" upper="2.0944" />
        <axis xyz="0 1 0" />
    </joint>
    <joint name="jRightHip_rotz" type="revolute">
        <origin xyz="0 0 0" rpy="0 0 0"/>
        <parent link="RightUpperLeg_f2"/>
        <child link="RightUpperLeg"/>
        <dynamics damping="0.1" friction="0.0"/>
        <limit effort="30" velocity="1.0" lower="-0.785398" upper="0.785398" />
        <axis xyz="0 0 1" />
    </joint>
	<joint name="jRightKnee_roty" type="revolute">
        <origin xyz="-6.6e-05           0    -0.48159" rpy="0 0 0"/>
        <parent link="RightUpperLeg"/>
        <child link="RightLowerLeg_f1"/>
        <dynamics damping="0.1" friction="0.0"/>
        <limit effort="30" velocity="1.0" lower="0" upper="2.35619" />
        <axis xyz="0 1 0" />
    </joint>
	<joint name="jRightKnee_rotz" type="revolute">
        <origin xyz="0 0 0" rpy="0 0 0"/>
        <parent link="RightLowerLeg_f1"/>
        <child link="RightLowerLeg"/>
        <dynamics damping="0.1" friction="0.0"/>
        <limit effort="30" velocity="1.0" lower="-0.698132" upper="0.523599" />
        <axis xyz="0 0 1" />
    </joint>
	<joint name="jRightAnkle_rotx" type="revolute">
        <origin xyz="1e-06           0    -0.47962" rpy="0 0 0"/>
        <parent link="RightLowerLeg"/>
        <child link="RightFoot_f1"/>
        <dynamics damping="0.1" friction="0.0"/>
        <limit effort="30" velocity="1.0" lower="-0.610865" upper="0.785398" />
        <axis xyz="1 0 0" />
    </joint>
	<joint name="jRightAnkle_roty" type="revolute">
        <origin xyz="0 0 0" rpy="0 0 0"/>
        <parent link="RightFoot_f1"/>
        <child link="RightFoot_f2"/>
        <dynamics damping="0.1" friction="0.0"/>
        <limit effort="30" velocity="1.0" lower="-0.523599" upper="0.872665" />
        <axis xyz="0 1 0" />
    </joint>
    <joint name="jRightAnkle_rotz" type="revolute">
        <origin xyz="0 0 0" rpy="0 0 0"/>
        <parent link="RightFoot_f2"/>
        <child link="RightFoot"/>
        <dynamics damping="0.1" friction="0.0"/>
        <limit effort="30" velocity="1.0" lower="-0.436332" upper="0.872665" />
        <axis xyz="0 0 1" />
    </joint>
	<joint name="jRightBallFoot_roty" type="revolute">
        <origin xyz="0.15123           0   -0.065325" rpy="0 0 0"/>
        <parent link="RightFoot"/>
        <child link="RightToe"/>
        <dynamics damping="0.1" friction="0.0"/>
        <limit effort="30" velocity="1.0" lower="-0.174533" upper="1.5708" />
        <axis xyz="0 1 0" />
    </joint>
	<!--Chain from (20) to (23)-->
	<joint name="jLeftHip_rotx" type="revolute">
        <origin xyz="0.000286    0.093433    0.002799" rpy="0 0 0"/>
        <parent link="Pelvis"/>
        <child link="LeftUpperLeg_f1"/>
        <dynamics damping="0.1" friction="0.0"/>
        <limit effort="30" velocity="1.0" lower="-0.523599" upper="0.785398" />
        <axis xyz="1 0 0" />
    </joint>
	<joint name="jLeftHip_roty" type="revolute">
        <origin xyz="0 0 0" rpy="0 0 0"/>
        <parent link="LeftUpperLeg_f1"/>
        <child link="LeftUpperLeg_f2"/>
        <dynamics damping="0.1" friction="0.0"/>
        <limit effort="30" velocity="1.0" lower="-0.261799" upper="2.0944" />
        <axis xyz="0 1 0" />
    </joint>
    <joint name="jLeftHip_rotz" type="revolute">
        <origin xyz="0 0 0" rpy="0 0 0"/>
        <parent link="LeftUpperLeg_f2"/>
        <child link="LeftUpperLeg"/>
        <dynamics damping="0.1" friction="0.0"/>
        <limit effort="30" velocity="1.0" lower="-0.785398" upper="0.785398" />
        <axis xyz="0 0 1" />
    </joint>
	<joint name="jLeftKnee_roty" type="revolute">
        <origin xyz="-6.6e-05           0    -0.48159" rpy="0 0 0"/>
        <parent link="LeftUpperLeg"/>
        <child link="LeftLowerLeg_f1"/>
        <dynamics damping="0.1" friction="0.0"/>
        <limit effort="30" velocity="1.0" lower="0" upper="2.35619" />
        <axis xyz="0 1 0" />
    </joint>
    <joint name="jLeftKnee_rotz" type="revolute">
        <origin xyz="0 0 0" rpy="0 0 0"/>
        <parent link="LeftLowerLeg_f1"/>
        <child link="LeftLowerLeg"/>
        <dynamics damping="0.1" friction="0.0"/>
        <limit effort="30" velocity="1.0" lower="-0.523599" upper="0.698132" />
        <axis xyz="0 0 1" />
    </joint>
	<joint name="jLeftAnkle_rotx" type="revolute">
        <origin xyz="1e-06           0    -0.47962" rpy="0 0 0"/>
        <parent link="LeftLowerLeg"/>
        <child link="LeftFoot_f1"/>
        <dynamics damping="0.1" friction="0.0"/>
        <limit effort="30" velocity="1.0" lower="-0.785398" upper="0.610865" />
        <axis xyz="1 0 0" />
    </joint>
	<joint name="jLeftAnkle_roty" type="revolute">
        <origin xyz="0 0 0" rpy="0 0 0"/>
        <parent link="LeftFoot_f1"/>
        <child link="LeftFoot_f2"/>
        <dynamics damping="0.1" friction="0.0"/>
        <limit effort="30" velocity="1.0" lower="-0.523599" upper="0.872665" />
        <axis xyz="0 1 0" />
    </joint>
    <joint name="jLeftAnkle_rotz" type="revolute">
        <origin xyz="0 0 0" rpy="0 0 0"/>
        <parent link="LeftFoot_f2"/>
        <child link="LeftFoot"/>
        <dynamics damping="0.1" friction="0.0"/>
        <limit effort="30" velocity="1.0" lower="-0.872665" upper="0.436332" />
        <axis xyz="0 0 1" />
    </joint>
	<joint name="jLeftBallFoot_roty" type="revolute">
        <origin xyz="0.15123           0   -0.065325" rpy="0 0 0"/>
        <parent link="LeftFoot"/>
        <child link="LeftToe"/>
        <dynamics damping="0.1" friction="0.0"/>
        <limit effort="30" velocity="1.0" lower="-0.174533" upper="1.5708" />
        <axis xyz="0 1 0" />
    </joint>

	<!-- Sensor  1-->
<sensor name="Pelvis_gyro" type="gyroscope">
<parent link="Pelvis"/>
<origin xyz="-0.064953  7.3342e-05     0.11133" rpy="0.18093      1.2598     -2.9441"/>
</sensor>
<sensor name="Pelvis_accelerometer" type="accelerometer">
<parent link="Pelvis"/>
<origin xyz="-0.064953  7.3342e-05     0.11133" rpy="0.18093      1.2598     -2.9441"/>
</sensor>
<!-- Sensor  2-->
<sensor name="T8_gyro" type="gyroscope">
<parent link="T8"/>
<origin xyz="0.13274 -3.5522e-05    0.072976" rpy="0.10969       1.201    -0.13773"/>
</sensor>
<sensor name="T8_accelerometer" type="accelerometer">
<parent link="T8"/>
<origin xyz="0.13274 -3.5522e-05    0.072976" rpy="0.10969       1.201    -0.13773"/>
</sensor>
<!-- Sensor  3-->
<sensor name="Head_gyro" type="gyroscope">
<parent link="Head"/>
<origin xyz="-0.078154  9.5957e-05    0.085802" rpy="1.9773     -0.1601     -1.7016"/>
</sensor>
<sensor name="Head_accelerometer" type="accelerometer">
<parent link="Head"/>
<origin xyz="-0.078154  9.5957e-05    0.085802" rpy="1.9773     -0.1601     -1.7016"/>
</sensor>
<!-- Sensor  4-->
<sensor name="RightShoulder_gyro" type="gyroscope">
<parent link="RightShoulder"/>
<origin xyz="-0.022346   -0.055932   -0.067036" rpy="1.2429    -0.30476     -1.4616"/>
</sensor>
<sensor name="RightShoulder_accelerometer" type="accelerometer">
<parent link="RightShoulder"/>
<origin xyz="-0.022346   -0.055932   -0.067036" rpy="1.2429    -0.30476     -1.4616"/>
</sensor>
<!-- Sensor  5-->
<sensor name="RightUpperArm_gyro" type="gyroscope">
<parent link="RightUpperArm"/>
<origin xyz="-0.021873    -0.10943    0.021884" rpy="0.02004    -0.11963     -1.6812"/>
</sensor>
<sensor name="RightUpperArm_accelerometer" type="accelerometer">
<parent link="RightUpperArm"/>
<origin xyz="-0.021873    -0.10943    0.021884" rpy="0.02004    -0.11963     -1.6812"/>
</sensor>
<!-- Sensor  6-->
<sensor name="RightForeArm_gyro" type="gyroscope">
<parent link="RightForeArm"/>
<origin xyz="0.0021274    -0.21903    0.021991" rpy="-0.61456   -0.082799     -1.3499"/>
</sensor>
<sensor name="RightForeArm_accelerometer" type="accelerometer">
<parent link="RightForeArm"/>
<origin xyz="0.0021274    -0.21903    0.021991" rpy="-0.61456   -0.082799     -1.3499"/>
</sensor>
<!-- Sensor  7-->
<sensor name="RightHand_gyro" type="gyroscope">
<parent link="RightHand"/>
<origin xyz="7.0533e-05   -0.060282    0.021961" rpy="-0.469   -0.050132     -1.5645"/>
</sensor>
<sensor name="RightHand_accelerometer" type="accelerometer">
<parent link="RightHand"/>
<origin xyz="7.0533e-05   -0.060282    0.021961" rpy="-0.469   -0.050132     -1.5645"/>
</sensor>
<!-- Sensor  8-->
<sensor name="LeftShoulder_gyro" type="gyroscope">
<parent link="LeftShoulder"/>
<origin xyz="-0.022432    0.055917   -0.067099" rpy="-1.0424     -0.2698       1.277"/>
</sensor>
<sensor name="LeftShoulder_accelerometer" type="accelerometer">
<parent link="LeftShoulder"/>
<origin xyz="-0.022432    0.055917   -0.067099" rpy="-1.0424     -0.2698       1.277"/>
</sensor>
<!-- Sensor  9-->
<sensor name="LeftUpperArm_gyro" type="gyroscope">
<parent link="LeftUpperArm"/>
<origin xyz="-0.021914     0.10939    0.021888" rpy="-0.12427   -0.032078      1.5431"/>
</sensor>
<sensor name="LeftUpperArm_accelerometer" type="accelerometer">
<parent link="LeftUpperArm"/>
<origin xyz="-0.021914     0.10939    0.021888" rpy="-0.12427   -0.032078      1.5431"/>
</sensor>
<!-- Sensor  10-->
<sensor name="LeftForeArm_gyro" type="gyroscope">
<parent link="LeftForeArm"/>
<origin xyz="0.0019854      0.2191    0.021912" rpy="0.45205   -0.015076       1.341"/>
</sensor>
<sensor name="LeftForeArm_accelerometer" type="accelerometer">
<parent link="LeftForeArm"/>
<origin xyz="0.0019854      0.2191    0.021912" rpy="0.45205   -0.015076       1.341"/>
</sensor>
<!-- Sensor  11-->
<sensor name="LeftHand_gyro" type="gyroscope">
<parent link="LeftHand"/>
<origin xyz="-2.7619e-05    0.060232     0.02196" rpy="0.24148   0.0024362      1.5452"/>
</sensor>
<sensor name="LeftHand_accelerometer" type="accelerometer">
<parent link="LeftHand"/>
<origin xyz="-2.7619e-05    0.060232     0.02196" rpy="0.24148   0.0024362      1.5452"/>
</sensor>
<!-- Sensor  12-->
<sensor name="RightUpperLeg_gyro" type="gyroscope">
<parent link="RightUpperLeg"/>
<origin xyz="0.01394   -0.049214     -0.2906" rpy="3.07      1.4018      1.5033"/>
</sensor>
<sensor name="RightUpperLeg_accelerometer" type="accelerometer">
<parent link="RightUpperLeg"/>
<origin xyz="0.01394   -0.049214     -0.2906" rpy="3.07      1.4018      1.5033"/>
</sensor>
<!-- Sensor  13-->
<sensor name="RightLowerLeg_gyro" type="gyroscope">
<parent link="RightLowerLeg"/>
<origin xyz="0.036327   0.0082782    -0.15582" rpy="-3.1219      1.4366     -2.7423"/>
</sensor>
<sensor name="RightLowerLeg_accelerometer" type="accelerometer">
<parent link="RightLowerLeg"/>
<origin xyz="0.036327   0.0082782    -0.15582" rpy="-3.1219      1.4366     -2.7423"/>
</sensor>
<!-- Sensor  14-->
<sensor name="RightFoot_gyro" type="gyroscope">
<parent link="RightFoot"/>
<origin xyz="0.087436   0.0013342   -0.012582" rpy="0.23261     0.45881    -0.16253"/>
</sensor>
<sensor name="RightFoot_accelerometer" type="accelerometer">
<parent link="RightFoot"/>
<origin xyz="0.087436   0.0013342   -0.012582" rpy="0.23261     0.45881    -0.16253"/>
</sensor>
<!-- Sensor  15-->
<sensor name="LeftUpperLeg_gyro" type="gyroscope">
<parent link="LeftUpperLeg"/>
<origin xyz="0.013998    0.049135    -0.29079" rpy="-2.8263      1.4339     -1.3177"/>
</sensor>
<sensor name="LeftUpperLeg_accelerometer" type="accelerometer">
<parent link="LeftUpperLeg"/>
<origin xyz="0.013998    0.049135    -0.29079" rpy="-2.8263      1.4339     -1.3177"/>
</sensor>
<!-- Sensor  16-->
<sensor name="LeftLowerLeg_gyro" type="gyroscope">
<parent link="LeftLowerLeg"/>
<origin xyz="0.036205  -0.0084208    -0.15595" rpy="2.5606      1.4033      2.3269"/>
</sensor>
<sensor name="LeftLowerLeg_accelerometer" type="accelerometer">
<parent link="LeftLowerLeg"/>
<origin xyz="0.036205  -0.0084208    -0.15595" rpy="2.5606      1.4033      2.3269"/>
</sensor>
<!-- Sensor  17-->
<sensor name="LeftFoot_gyro" type="gyroscope">
<parent link="LeftFoot"/>
<origin xyz="0.087269  -0.0015436   -0.012394" rpy="0.0012317     0.58393     0.19088"/>
</sensor>
<sensor name="LeftFoot_accelerometer" type="accelerometer">
<parent link="LeftFoot"/>
<origin xyz="0.087269  -0.0015436   -0.012394" rpy="0.0012317     0.58393     0.19088"/>
</sensor>


</robot>
