<!--URDF MODEL 48 DoFs-->

<robot name="XSensStyleModel_template">
<!--To open this model with Gazebo replace the null masses, inertias and dimensions of the 'fake links f1 and f2'-->
    <!--LINKS-->
	<!--Link base (1)-->
	<link name="Pelvis">
        <inertial>
            <mass value="4.416"/>
			<!--COM origin wrt pHipOrigin-->
            <origin xyz="0           0    0.054579" rpy="0 0 0" />
            <inertia ixx="0.032646" iyy="0.012663" izz="0.036997" ixy="0" ixz="0" iyz="0"/>
        </inertial>

        <visual>
			<!--box origin wrt pHipOrigin-->
            <origin xyz="0           0    0.054579" rpy="0 0 0" />
            <geometry>
                <box size="0.15204     0.27824     0.10627"/>
            </geometry>
        </visual>

        <collision>
			<!--box origin wrt pHipOrigin-->
            <origin xyz="0           0    0.054579" rpy="0 0 0" />
            <geometry>
                <box size="0.15204     0.27824     0.10627"/>
            </geometry>
        </collision>

    </link>
    <!--Chain from (2) to (7)-->
	<link name="L5_f1">
        <inertial>
            <mass value="0"/>
            <origin xyz="0 0 0" rpy="0 0 0" />
            <inertia ixx="0" iyy="0" izz="0" ixy="0" ixz="0" iyz="0"/>
        </inertial>
    </link>
	<link name="L5">
        <inertial>
            <mass value="5.6304"/>
			<!--COM origin wrt jL5S1-->
            <origin xyz="0           0    0.046545" rpy="0 0 0" />
            <inertia ixx="0.019207" iyy="0.014912" izz="0.025988" ixy="0" ixz="0" iyz="0"/>
        </inertial>

        <visual>
			<!--box origin origin wrt jL5S1-->
            <origin xyz="0           0    0.046545" rpy="0 0 0" />
            <geometry>
                <box size="0.15204     0.17964     0.09309"/>
            </geometry>
        </visual>

        <collision>
			<!--box origin origin wrt jL5S1-->
            <origin xyz="0           0    0.046545" rpy="0 0 0" />
            <geometry>
                <box size="0.15204     0.17964     0.09309"/>
            </geometry>
        </collision>
    </link>
	<link name="L3_f1">
        <inertial>
            <mass value="0"/>
            <origin xyz="0 0 0" rpy="0 0 0" />
            <inertia ixx="0" iyy="0" izz="0" ixy="0" ixz="0" iyz="0"/>
        </inertial>
    </link>
	<link name="L3">
        <inertial>
            <mass value="5.6304"/>
			<!--COM origin wrt jL4L3-->
            <origin xyz="0           0    0.042046" rpy="0 0 0" />
            <inertia ixx="0.018459" iyy="0.014164" izz="0.025988" ixy="0" ixz="0" iyz="0"/>
        </inertial>

        <visual>
			<!--box origin origin wrt jL4L3-->
            <origin xyz="0           0    0.042046" rpy="0 0 0" />
            <geometry>
                <box size="0.15204     0.17964    0.084092"/>
            </geometry>
        </visual>

        <collision>
			<!--box origin origin wrt jL4L3-->
            <origin xyz="0           0    0.042046" rpy="0 0 0" />
            <geometry>
                <box size="0.15204     0.17964    0.084092"/>
            </geometry>
        </collision>
    </link>
	<link name="T12_f1">
        <inertial>
            <mass value="0"/>
            <origin xyz="0 0 0" rpy="0 0 0" />
            <inertia ixx="0" iyy="0" izz="0" ixy="0" ixz="0" iyz="0"/>
        </inertial>
    </link>
	<link name="T12">
        <inertial>
            <mass value="5.6304"/>
			<!--COM origin wrt jL1T12-->
            <origin xyz="0           0    0.042046" rpy="0 0 0" />
            <inertia ixx="0.018459" iyy="0.014164" izz="0.025988" ixy="0" ixz="0" iyz="0"/>
        </inertial>

        <visual>
			<!--box origin origin wrt jL1T12-->
            <origin xyz="0           0    0.042046" rpy="0 0 0" />
            <geometry>
                <box size="0.15204     0.17964    0.084092"/>
            </geometry>
        </visual>

        <collision>
			<!--box origin origin wrt jL1T12-->
            <origin xyz="0           0    0.042046" rpy="0 0 0" />
            <geometry>
                <box size="0.15204     0.17964    0.084092"/>
            </geometry>
        </collision>
    </link>
	<link name="T8_f1">
        <inertial>
            <mass value="0"/>
            <origin xyz="0 0 0" rpy="0 0 0" />
            <inertia ixx="0" iyy="0" izz="0" ixy="0" ixz="0" iyz="0"/>
        </inertial>
    </link>
	<link name="T8_f2">
        <inertial>
            <mass value="0"/>
            <origin xyz="0 0 0" rpy="0 0 0" />
            <inertia ixx="0" iyy="0" izz="0" ixy="0" ixz="0" iyz="0"/>
        </inertial>
    </link>
	<link name="T8">
        <inertial>
            <mass value="2.208"/>
			<!--COM origin wrt jT9T8-->
            <origin xyz="0           0    0.059077" rpy="0 0 0" />
            <inertia ixx="0.0031087" iyy="0.0059088" izz="0.00388" ixy="0" ixz="0" iyz="0"/>
        </inertial>

        <visual>
			<!--box origin wrt jT9T8-->
            <origin xyz="0           0    0.059077" rpy="0 0 0" />
            <geometry>
                <box size="0.13473    0.054172     0.11815"/>
            </geometry>
        </visual>

        <collision>
			<!--box origin wrt jT9T8-->
            <origin xyz="0           0    0.059077" rpy="0 0 0" />
            <geometry>
                <box size="0.13473    0.054172     0.11815"/>
            </geometry>
        </collision>

    </link>
	<link name="Neck_f1">
        <inertial>
            <mass value="0"/>
            <origin xyz="0 0 0" rpy="0 0 0" />
            <inertia ixx="0" iyy="0" izz="0" ixy="0" ixz="0" iyz="0"/>
        </inertial>
    </link>
	<link name="Neck_f2">
        <inertial>
            <mass value="0"/>
            <origin xyz="0 0 0" rpy="0 0 0" />
            <inertia ixx="0" iyy="0" izz="0" ixy="0" ixz="0" iyz="0"/>
        </inertial>
    </link>
	<link name="Neck">
        <inertial>
            <mass value="0.6624"/>
			<!--COM origin wrt jT1C7-->
            <origin xyz="0           0    0.043276" rpy="0 0 0" />
            <inertia ixx="0.00054354" iyy="0.00054354" izz="0.00026007" ixy="0" ixz="0" iyz="0"/>
        </inertial>

        <visual>
			<!--box origin wrt jT1C7-->
            <origin xyz="0           0    0.043276" rpy="0 0 0" />
            <geometry>
		<cylinder length="0.086551" radius="0.014011"/>
            </geometry>
        </visual>

        <collision>
			<!--box origin wrt jT1C7-->
            <origin xyz="0           0    0.043276" rpy="0 0 0" />
            <geometry>
                <cylinder length="0.086551" radius="0.014011"/>
            </geometry>
        </collision>
    </link>
	<link name="Head_f1">
        <inertial>
            <mass value="0"/>
            <origin xyz="0 0 0" rpy="0 0 0" />
            <inertia ixx="0" iyy="0" izz="0" ixy="0" ixz="0" iyz="0"/>
        </inertial>
    </link>
	<link name="Head">
        <inertial>
            <mass value="1.9872"/>
			<!--COM origin wrt jC1Head-->
            <origin xyz="0           0    0.085351" rpy="0 0 0" />
            <inertia ixx="0.0057906" iyy="0.0057906" izz="0.0057906" ixy="0" ixz="0" iyz="0"/>
        </inertial>

        <visual>
			<!--boc origin wrt jC1Head-->
            <origin xyz="0           0    0.085351" rpy="0 0 0" />
            <geometry>
                <sphere radius="0.085351"/>
            </geometry>
        </visual>

        <collision>
			<!--box origin wrt jC1Head-->
            <origin xyz="0           0    0.085351" rpy="0 0 0" />
            <geometry>
                <sphere radius="0.085351"/>
            </geometry>
        </collision>

    </link>
	<!--Chain from (8) to (11)-->
	<link name="RightShoulder">
        <inertial>
            <mass value="1.7112"/>
			<!--COM origin wrt jRightC7Shoulder-->
            <origin xyz="0   -0.068449           0" rpy="0 0 0" />
            <inertia ixx="0.0029297" iyy="0.00051445" izz="0.0029297" ixy="0" ixz="0" iyz="0"/>
        </inertial>

        <visual>
			<!--box origin wrt jRightC7Shoulder. RPY rotated of pi/2.-->
            <origin xyz="0   -0.068449           0" rpy="1.5708 0 0" />
            <geometry>
                <cylinder length="0.1369" radius="0.024521"/>
            </geometry>
        </visual>

        <collision>
			<!--box origin wrt jRightC7Shoulder. RPY rotated of pi/2.-->
            <origin xyz="0   -0.068449           0" rpy="1.5708 0 0" />
            <geometry>
                <cylinder length="0.1369" radius="0.024521"/>
            </geometry>
        </collision>

    </link>
	<link name="RightUpperArm_f1">
        <inertial>
            <mass value="0"/>
            <origin xyz="0 0 0" rpy="0 0 0" />
            <inertia ixx="0" iyy="0" izz="0" ixy="0" ixz="0" iyz="0"/>
        </inertial>
    </link>
	<link name="RightUpperArm_f2">
        <inertial>
            <mass value="0"/>
            <origin xyz="0 0 0" rpy="0 0 0" />
            <inertia ixx="0" iyy="0" izz="0" ixy="0" ixz="0" iyz="0"/>
        </inertial>
    </link>
    <link name="RightUpperArm">
        <inertial>
            <mass value="1.656"/>
			<!--COM origin wrt jRightShoulder-->
            <origin xyz="0    -0.14097           0" rpy="0 0 0" />
            <inertia ixx="0.011359" iyy="0.00077855" izz="0.011359" ixy="0" ixz="0" iyz="0"/>
        </inertial>

        <visual>
			<!--box origin wrt jRightShoulder. RPY rotated of pi/2.-->
            <origin xyz="0    -0.14097           0" rpy="1.5708 0 0" />
            <geometry>
                <cylinder length="0.28194" radius="0.030664"/>
            </geometry>
        </visual>

        <collision>
			<!--box origin wrt jRightShoulder. RPY rotated of pi/2.-->
            <origin xyz="0    -0.14097           0" rpy="1.5708 0 0" />
            <geometry>
                <cylinder length="0.28194" radius="0.030664"/>
            </geometry>
        </collision>

    </link>
	<link name="RightForeArm_f1">
        <inertial>
            <mass value="0"/>
            <origin xyz="0 0 0" rpy="0 0 0" />
            <inertia ixx="0" iyy="0" izz="0" ixy="0" ixz="0" iyz="0"/>
        </inertial>
    </link>
	<link name="RightForeArm">
        <inertial>
            <mass value="1.104"/>
			<!--COM origin wrt jRightElbow-->
            <origin xyz="0    -0.11576           0" rpy="0 0 0" />
            <inertia ixx="0.0050467" iyy="0.00023068" izz="0.0050467" ixy="0" ixz="0" iyz="0"/>
        </inertial>

        <visual>
			<!--box origin wrt jRightElbow. RPY rotated of pi/2.-->
            <origin xyz="0    -0.11576           0" rpy="1.5708 0 0" />
            <geometry>
                <cylinder length="0.23152" radius="0.020443"/>
            </geometry>
        </visual>

        <collision>
			<!--box origin wrt jRightElbow. RPY rotated of pi/2.-->
            <origin xyz="0    -0.11576           0" rpy="1.5708 0 0" />
            <geometry>
                <cylinder length="0.23152" radius="0.020443"/>
            </geometry>
        </collision>

    </link>
	<link name="RightHand_f1">
        <inertial>
            <mass value="0"/>
            <origin xyz="0 0 0" rpy="0 0 0" />
            <inertia ixx="0" iyy="0" izz="0" ixy="0" ixz="0" iyz="0"/>
        </inertial>
    </link>
	<link name="RightHand">
        <inertial>
            <mass value="0.3312"/>
			<!--COM origin wrt jRightWrist-->
            <origin xyz="0   -0.086727           0" rpy="0 0 0" />
            <inertia ixx="0.00087653" iyy="0.0004152" izz="0.0011995" ixy="0" ixz="0" iyz="0"/>
        </inertial>

        <visual>
			<!--box origin wrt jRightWrist-->
            <origin xyz="0   -0.086727           0" rpy="0 0 0" />
            <geometry>
                <box size="0.11564     0.17345    0.040885"/>
            </geometry>
        </visual>

        <collision>
			<!--box origin wrt jRightWrist-->
            <origin xyz="0   -0.086727           0" rpy="0 0 0" />
            <geometry>
                <box size="0.11564     0.17345    0.040885"/>
            </geometry>
        </collision>

    </link>
	<!--Chain from (12) to (15)-->
	<link name="LeftShoulder">
        <inertial>
            <mass value="1.7112"/>
			<!--COM origin wrt jLeftC7Shoulder-->
            <origin xyz="0    0.068449           0" rpy="0 0 0" />
            <inertia ixx="0.0029297" iyy="0.00051445" izz="0.0029297" ixy="0" ixz="0" iyz="0"/>
        </inertial>

        <visual>
			<!--box origin wrt jLeftC7Shoulder. RPY rotated of pi/2.-->
            <origin xyz="0    0.068449           0" rpy="1.5708 0 0" />
            <geometry>
                <cylinder length="0.1369" radius="0.024521"/>
            </geometry>
        </visual>

        <collision>
			<!--box origin wrt jLeftC7Shoulder. RPY rotated of pi/2.-->
            <origin xyz="0    0.068449           0" rpy="1.5708 0 0" />
            <geometry>
                <cylinder length="0.1369" radius="0.024521"/>
            </geometry>
        </collision>

    </link>
	<link name="LeftUpperArm_f1">
        <inertial>
            <mass value="0"/>
            <origin xyz="0 0 0" rpy="0 0 0" />
            <inertia ixx="0" iyy="0" izz="0" ixy="0" ixz="0" iyz="0"/>
        </inertial>
    </link>
	<link name="LeftUpperArm_f2">
        <inertial>
            <mass value="0"/>
            <origin xyz="0 0 0" rpy="0 0 0" />
            <inertia ixx="0" iyy="0" izz="0" ixy="0" ixz="0" iyz="0"/>
        </inertial>
    </link>
	<link name="LeftUpperArm">
        <inertial>
            <mass value="1.656"/>
			<!--COM origin wrt jLeftShoulder-->
            <origin xyz="0     0.14097           0" rpy="0 0 0" />
            <inertia ixx="0.011359" iyy="0.00077855" izz="0.011359" ixy="0" ixz="0" iyz="0"/>
        </inertial>

        <visual>
			<!--box origin wrt jLeftShoulder. RPY rotated of pi/2.-->
            <origin xyz="0     0.14097           0" rpy="1.5708 0 0" />
            <geometry>
                <cylinder length="0.28194" radius="0.030664"/>
            </geometry>
        </visual>

        <collision>
			<!--box origin wrt jLeftShoulder. RPY rotated of pi/2.-->
            <origin xyz="0     0.14097           0" rpy="1.5708 0 0" />
            <geometry>
                <cylinder length="0.28194" radius="0.030664"/>
            </geometry>
        </collision>

    </link>
	<link name="LeftForeArm_f1">
        <inertial>
            <mass value="0"/>
            <origin xyz="0 0 0" rpy="0 0 0" />
            <inertia ixx="0" iyy="0" izz="0" ixy="0" ixz="0" iyz="0"/>
        </inertial>
    </link>
	<link name="LeftForeArm">
        <inertial>
            <mass value="1.104"/>
			<!--COM origin wrt jLeftElbow-->
            <origin xyz="0     0.11576           0" rpy="0 0 0" />
            <inertia ixx="0.0050467" iyy="0.00023068" izz="0.0050467" ixy="0" ixz="0" iyz="0"/>
        </inertial>

        <visual>
			<!--box origin wrt jLeftElbow. RPY rotated of pi/2.-->
            <origin xyz="0     0.11576           0" rpy="1.5708 0 0" />
            <geometry>
                <cylinder length="0.23152" radius="0.020443"/>
            </geometry>
        </visual>

        <collision>
			<!--box origin wrt jLeftElbow. RPY rotated of pi/2.-->
            <origin xyz="0     0.11576           0" rpy="1.5708 0 0" />
            <geometry>
                <cylinder length="0.23152" radius="0.020443"/>
            </geometry>
        </collision>

    </link>
	<link name="LeftHand_f1">
        <inertial>
            <mass value="0"/>
            <origin xyz="0 0 0" rpy="0 0 0" />
            <inertia ixx="0" iyy="0" izz="0" ixy="0" ixz="0" iyz="0"/>
        </inertial>
    </link>
	<link name="LeftHand">
        <inertial>
            <mass value="0.3312"/>
			<!--COM origin wrt jLeftWrist-->
            <origin xyz="0    0.086727           0" rpy="0 0 0" />
            <inertia ixx="0.00087653" iyy="0.0004152" izz="0.0011995" ixy="0" ixz="0" iyz="0"/>
        </inertial>

        <visual>
			<!--COM origin wrt jLeftWrist-->
            <origin xyz="0    0.086727           0" rpy="0 0 0" />
            <geometry>
                <box size="0.11564     0.17345    0.040885"/>
            </geometry>
        </visual>

        <collision>
			<!--COM origin wrt jLeftWrist-->
            <origin xyz="0    0.086727           0" rpy="0 0 0" />
            <geometry>
                <box size="0.11564     0.17345    0.040885"/>
            </geometry>
        </collision>

    </link>
	<!--Chain from (16) to (19)-->
	<link name="RightUpperLeg_f1">
        <inertial>
            <mass value="0"/>
            <origin xyz="0 0 0" rpy="0 0 0" />
            <inertia ixx="0" iyy="0" izz="0" ixy="0" ixz="0" iyz="0"/>
        </inertial>
    </link>
	<link name="RightUpperLeg_f2">
        <inertial>
            <mass value="0"/>
            <origin xyz="0 0 0" rpy="0 0 0" />
            <inertia ixx="0" iyy="0" izz="0" ixy="0" ixz="0" iyz="0"/>
        </inertial>
    </link>
    <link name="RightUpperLeg">
        <inertial>
            <mass value="6.9"/>
			<!--COM origin wrt jRightHip-->
            <origin xyz="0           0    -0.23539" rpy="0 0 0" />
            <inertia ixx="0.13349" iyy="0.13349" izz="0.012102" ixy="0" ixz="0" iyz="0"/>
        </inertial>

        <visual>
			<!--box origin wrt jRightHip-->
            <origin xyz="0           0    -0.23539" rpy="0 0 0" />
            <geometry>
                <cylinder length="0.47078" radius="0.059228"/>
            </geometry>
        </visual>

        <collision>
			<!--box origin wrt jRightHip-->
            <origin xyz="0           0    -0.23539" rpy="0 0 0" />
            <geometry>
                <cylinder length="0.47078" radius="0.059228"/>
            </geometry>
        </collision>

    </link>
	<link name="RightLowerLeg_f1">
        <inertial>
            <mass value="0"/>
            <origin xyz="0 0 0" rpy="0 0 0" />
            <inertia ixx="0" iyy="0" izz="0" ixy="0" ixz="0" iyz="0"/>
        </inertial>
    </link>
    <link name="RightLowerLeg">
        <inertial>
            <mass value="2.0148"/>
			<!--COM origin wrt jRightKnee-->
            <origin xyz="0           0    -0.18629" rpy="0 0 0" />
            <inertia ixx="0.023906" iyy="0.023906" izz="0.0012007" ixy="0" ixz="0" iyz="0"/>
        </inertial>

        <visual>
			<!--box origin wrt jRightKnee-->
            <origin xyz="0           0    -0.18629" rpy="0 0 0" />
            <geometry>
                <cylinder length="0.37257" radius="0.034524"/>
            </geometry>
        </visual>

        <collision>
			<!--box origin wrt jRightKnee-->
            <origin xyz="0           0    -0.18629" rpy="0 0 0" />
            <geometry>
                <cylinder length="0.37257" radius="0.034524"/>
            </geometry>
        </collision>

    </link>
	<link name="RightFoot_f1">
        <inertial>
            <mass value="0"/>
            <origin xyz="0 0 0" rpy="0 0 0" />
            <inertia ixx="0" iyy="0" izz="0" ixy="0" ixz="0" iyz="0"/>
        </inertial>
    </link>
	<link name="RightFoot_f2">
        <inertial>
            <mass value="0"/>
            <origin xyz="0 0 0" rpy="0 0 0" />
            <inertia ixx="0" iyy="0" izz="0" ixy="0" ixz="0" iyz="0"/>
        </inertial>
    </link>
    <link name="RightFoot">
        <inertial>
            <mass value="0.7176"/>
			<!--COM origin wrt jRightAnkle-->
            <origin xyz="0.055949           0   -0.039369" rpy="0 0 0" />
            <inertia ixx="0.00065584" iyy="0.0024234" izz="0.0023377" ixy="0" ixz="0" iyz="0"/>
        </inertial>

        <visual>
			<!--box origin wrt jRightAnkle-->
	    	<origin xyz="0.055949           0   -0.039369" rpy="0 0 0" />
            <geometry>
                <box size="0.18527    0.069048    0.078737"/>
            </geometry>
        </visual>

        <collision>
			<!--box origin wrt jRightAnkle-->
		    <origin xyz="0.055949           0   -0.039369" rpy="0 0 0" />
	            <geometry>
	                <box size="0.18527    0.069048    0.078737"/>
	            </geometry>
        </collision>

    </link>
    <link name="RightToe">
        <inertial>
            <mass value="0.0828"/>
			<!--COM origin wrt jRightBallFoot-->
            <origin xyz="0.032364           0           0" rpy="0 0 0" />
            <inertia ixx="3.4446e-05" iyy="3.046e-05" izz="6.1807e-05" ixy="0" ixz="0" iyz="0"/>
        </inertial>

        <visual>
			<!--box origin wrt jRightBallFoot-->
            <origin xyz="0.032364           0           0" rpy="0 0 0" />
            <geometry>
                <box size="0.064729    0.069048    0.014986"/>
            </geometry>
        </visual>

        <collision>
			<!--box origin wrt jRightBallFoot-->
            <origin xyz="0.032364           0           0" rpy="0 0 0" />
            <geometry>
                <box size="0.064729    0.069048    0.014986"/>
            </geometry>
        </collision>
    </link>
	<!--Chain from (20) to (23)-->
	<link name="LeftUpperLeg_f1">
        <inertial>
            <mass value="0"/>
            <origin xyz="0 0 0" rpy="0 0 0" />
            <inertia ixx="0" iyy="0" izz="0" ixy="0" ixz="0" iyz="0"/>
        </inertial>
    </link>
	<link name="LeftUpperLeg_f2">
        <inertial>
            <mass value="0"/>
            <origin xyz="0 0 0" rpy="0 0 0" />
            <inertia ixx="0" iyy="0" izz="0" ixy="0" ixz="0" iyz="0"/>
        </inertial>
    </link>
    <link name="LeftUpperLeg">
        <inertial>
            <mass value="6.9"/>
			<!--COM origin wrt jLeftHip-->
            <origin xyz="0           0    -0.23539" rpy="0 0 0" />
            <inertia ixx="0.13349" iyy="0.13349" izz="0.012102" ixy="0" ixz="0" iyz="0"/>
        </inertial>

        <visual>
			<!--box origin wrt jLeftHip-->
            <origin xyz="0           0    -0.23539" rpy="0 0 0" />
            <geometry>
                <cylinder length="0.47078" radius="0.059228"/>
            </geometry>
        </visual>

        <collision>
			<!--box origin wrt jLeftHip-->
            <origin xyz="0           0    -0.23539" rpy="0 0 0" />
            <geometry>
                <cylinder length="0.47078" radius="0.059228"/>
            </geometry>
        </collision>

    </link>
	<link name="LeftLowerLeg_f1">
        <inertial>
            <mass value="0"/>
            <origin xyz="0 0 0" rpy="0 0 0" />
            <inertia ixx="0" iyy="0" izz="0" ixy="0" ixz="0" iyz="0"/>
        </inertial>
    </link>
	<link name="LeftLowerLeg">
        <inertial>
            <mass value="2.0148"/>
			<!--COM origin wrt jLeftKnee-->
            <origin xyz="0           0    -0.18629" rpy="0 0 0" />
            <inertia ixx="0.023906" iyy="0.023906" izz="0.0012007" ixy="0" ixz="0" iyz="0"/>
        </inertial>

        <visual>
			<!--box origin wrt jLeftKnee-->
            <origin xyz="0           0    -0.18629" rpy="0 0 0" />
            <geometry>
		<cylinder length="0.37257" radius="0.034524"/>
            </geometry>
        </visual>

        <collision>
			<!--box origin wrt jLeftKnee-->
            <origin xyz="0           0    -0.18629" rpy="0 0 0" />
            <geometry>
		<cylinder length="0.37257" radius="0.034524"/>
            </geometry>
        </collision>

    </link>
	<link name="LeftFoot_f1">
        <inertial>
            <mass value="0"/>
            <origin xyz="0 0 0" rpy="0 0 0" />
            <inertia ixx="0" iyy="0" izz="0" ixy="0" ixz="0" iyz="0"/>
        </inertial>
    </link>
	<link name="LeftFoot_f2">
        <inertial>
            <mass value="0"/>
            <origin xyz="0 0 0" rpy="0 0 0" />
            <inertia ixx="0" iyy="0" izz="0" ixy="0" ixz="0" iyz="0"/>
        </inertial>
    </link>
    <link name="LeftFoot">
        <inertial>
            <mass value="0.7176"/>
			<!--COM origin wrt jLeftAnkle-->
            <origin xyz="0.055949           0   -0.039369" rpy="0 0 0" />
            <inertia ixx="0.00065584" iyy="0.0024234" izz="0.0023377" ixy="0" ixz="0" iyz="0"/>
        </inertial>

        <visual>
			<!--box origin wrt jLeftAnkle-->
	   	 	<origin xyz="0.055949           0   -0.039369" rpy="0 0 0" />
            <geometry>
                <box size="0.18527    0.069048    0.078737"/>
            </geometry>
        </visual>

        <collision>
			<!--box origin wrt jLeftAnkle-->
		    <origin xyz="0.055949           0   -0.039369" rpy="0 0 0" />
	            <geometry>
	                <box size="0.18527    0.069048    0.078737"/>
	            </geometry>
        </collision>

    </link>
	<link name="LeftToe">
        <inertial>
            <mass value="0.0828"/>
			<!--COM origin wrt jLeftBallFoot-->
            <origin xyz="0.032364           0           0" rpy="0 0 0" />
            <inertia ixx="3.4446e-05" iyy="3.046e-05" izz="6.1807e-05" ixy="0" ixz="0" iyz="0"/>
        </inertial>

        <visual>
			<!--box origin wrt jLeftBallFoot-->
            <origin xyz="0.032364           0           0" rpy="0 0 0" />
            <geometry>
                <box size="0.064729    0.069048    0.014986"/>
            </geometry>
        </visual>

        <collision>
			<!--box origin wrt jLeftBallFoot-->
            <origin xyz="0.032364           0           0" rpy="0 0 0" />
            <geometry>
                <box size="0.064729    0.069048    0.014986"/>
            </geometry>
        </collision>
    </link>


	<!--JOINTS-->
	<!--Chain from (2) to (7)-->
	<joint name="jL5S1_rotx" type="revolute">
        <origin xyz="-0.000294           0     0.10772" rpy="0 0 0"/>
        <parent link="Pelvis"/>
        <child link="L5_f1"/>
        <dynamics damping="0.1" friction="0.0"/>
        <limit effort="30" velocity="1.0" lower="-0.610865" upper="0.610865" />
        <axis xyz="1 0 0" />
    </joint>
	<joint name="jL5S1_roty" type="revolute">
        <origin xyz="0 0 0" rpy="0 0 0"/>
        <parent link="L5_f1"/>
        <child link="L5"/>
        <dynamics damping="0.1" friction="0.0"/>
        <limit effort="30" velocity="1.0" lower="-0.523599" upper="1.309" />
        <axis xyz="0 1 0" />
    </joint>
	<joint name="jL4L3_rotx" type="revolute">
        <origin xyz="0.000535           0     0.09309" rpy="0 0 0"/>
        <parent link="L5"/>
        <child link="L3_f1"/>
        <dynamics damping="0.1" friction="0.0"/>
        <limit effort="30" velocity="1.0" lower="-0.610865" upper="0.610865" />
        <axis xyz="1 0 0" />
    </joint>
	<joint name="jL4L3_roty" type="revolute">
        <origin xyz="0 0 0" rpy="0 0 0"/>
        <parent link="L3_f1"/>
        <child link="L3"/>
        <dynamics damping="0.1" friction="0.0"/>
        <limit effort="30" velocity="1.0" lower="-0.523599" upper="1.309" />
        <axis xyz="0 1 0" />
    </joint>
	<joint name="jL1T12_rotx" type="revolute">
        <origin xyz="0           0    0.084092" rpy="0 0 0"/>
        <parent link="L3"/>
        <child link="T12_f1"/>
        <dynamics damping="0.1" friction="0.0"/>
        <limit effort="30" velocity="1.0" lower="-0.610865" upper="0.610865" />
        <axis xyz="1 0 0" />
    </joint>
	<joint name="jL1T12_roty" type="revolute">
        <origin xyz="0 0 0" rpy="0 0 0"/>
        <parent link="T12_f1"/>
        <child link="T12"/>
        <dynamics damping="0.1" friction="0.0"/>
        <limit effort="30" velocity="1.0" lower="-0.523599" upper="1.309" />
        <axis xyz="0 1 0" />
    </joint>
	<joint name="jT9T8_rotx" type="revolute">
        <origin xyz="0           0    0.084092" rpy="0 0 0"/>
        <parent link="T12"/>
        <child link="T8_f1"/>
        <dynamics damping="0.1" friction="0.0"/>
        <limit effort="30" velocity="1.0" lower="-0.349066" upper="0.349066" />
        <axis xyz="1 0 0" />
    </joint>
	<joint name="jT9T8_roty" type="revolute">
        <origin xyz="0 0 0" rpy="0 0 0"/>
        <parent link="T8_f1"/>
        <child link="T8_f2"/>
        <dynamics damping="0.1" friction="0.0"/>
        <limit effort="30" velocity="1.0" lower="-0.261799" upper="0.698132" />
        <axis xyz="0 1 0" />
    </joint>
    <joint name="jT9T8_rotz" type="revolute">
        <origin xyz="0 0 0" rpy="0 0 0"/>
        <parent link="T8_f2"/>
        <child link="T8"/>
        <dynamics damping="0.1" friction="0.0"/>
        <limit effort="30" velocity="1.0" lower="-0.610865" upper="0.610865" />
        <axis xyz="0 0 1" />
    </joint>
	<joint name="jT1C7_rotx" type="revolute">
        <origin xyz="0           0     0.11815" rpy="0 0 0"/>
        <parent link="T8"/>
        <child link="Neck_f1"/>
        <dynamics damping="0.1" friction="0.0"/>
        <limit effort="30" velocity="1.0" lower="-0.610865" upper="0.610865" />
        <axis xyz="1 0 0" />
    </joint>
	<joint name="jT1C7_roty" type="revolute">
        <origin xyz="0 0 0" rpy="0 0 0"/>
        <parent link="Neck_f1"/>
        <child link="Neck_f2"/>
        <dynamics damping="0.1" friction="0.0"/>
        <limit effort="30" velocity="1.0" lower="-0.959931" upper="1.5708" />
        <axis xyz="0 1 0" />
    </joint>
    <joint name="jT1C7_rotz" type="revolute">
        <origin xyz="0 0 0" rpy="0 0 0"/>
        <parent link="Neck_f2"/>
        <child link="Neck"/>
        <dynamics damping="0.1" friction="0.0"/>
        <limit effort="30" velocity="1.0" lower="-1.22173" upper="1.22173" />
        <axis xyz="0 0 1" />
    </joint>
	<joint name="jC1Head_rotx" type="revolute">
        <origin xyz="0.00062           0    0.086551" rpy="0 0 0"/>
        <parent link="Neck"/>
        <child link="Head_f1"/>
        <dynamics damping="0.1" friction="0.0"/>
        <limit effort="30" velocity="1.0" lower="-0.610865" upper="0.610865" />
        <axis xyz="1 0 0" />
    </joint>
	<joint name="jC1Head_roty" type="revolute">
        <origin xyz="0 0 0" rpy="0 0 0"/>
        <parent link="Head_f1"/>
        <child link="Head"/>
        <dynamics damping="0.1" friction="0.0"/>
        <limit effort="30" velocity="1.0" lower="-0.436332" upper="0.174533" />
        <axis xyz="0 1 0" />
    </joint>
	<!--Chain from (8) to (11)-->
	<joint name="jRightC7Shoulder_rotx" type="revolute">
        <origin xyz="0   -0.027086    0.066263" rpy="0 0 0"/>
        <parent link="T8"/>
        <child link="RightShoulder"/>
        <dynamics damping="0.1" friction="0.0"/>
        <limit effort="30" velocity="1.0" lower="-0.785398" upper="0.0872665" />
        <axis xyz="1 0 0" />
    </joint>
	<joint name="jRightShoulder_rotx" type="revolute">
        <origin xyz="0     -0.1369           0" rpy="0 0 0"/>
        <parent link="RightShoulder"/>
        <child link="RightUpperArm_f1"/>
        <dynamics damping="0.1" friction="0.0"/>
        <limit effort="30" velocity="1.0" lower="-2.35619" upper="1.5708" />
        <axis xyz="1 0 0" />
    </joint>
	<joint name="jRightShoulder_roty" type="revolute">
        <origin xyz="0 0 0" rpy="0 0 0"/>
        <parent link="RightUpperArm_f1"/>
        <child link="RightUpperArm_f2"/>
        <dynamics damping="0.1" friction="0.0"/>
        <limit effort="30" velocity="1.0" lower="-1.5708" upper="1.5708" />
        <axis xyz="0 1 0" />
    </joint>
    <joint name="jRightShoulder_rotz" type="revolute">
        <origin xyz="0 0 0" rpy="0 0 0"/>
        <parent link="RightUpperArm_f2"/>
        <child link="RightUpperArm"/>
        <dynamics damping="0.1" friction="0.0"/>
        <limit effort="30" velocity="1.0" lower="-0.785398" upper="3.14159" />
        <axis xyz="0 0 1" />
    </joint>
	<joint name="jRightElbow_roty" type="revolute">
        <origin xyz="0    -0.28194           0" rpy="0 0 0"/>
        <parent link="RightUpperArm"/>
        <child link="RightForeArm_f1"/>
        <dynamics damping="0.1" friction="0.0"/>
        <limit effort="30" velocity="1.0" lower="-1.5708" upper="1.48353" />
        <axis xyz="0 1 0" />
    </joint>
	<joint name="jRightElbow_rotz" type="revolute">
        <origin xyz="0 0 0" rpy="0 0 0"/>
        <parent link="RightForeArm_f1"/>
        <child link="RightForeArm"/>
        <dynamics damping="0.1" friction="0.0"/>
        <limit effort="30" velocity="1.0" lower="0" upper="2.53073" />
        <axis xyz="0 0 1" />
    </joint>
	<joint name="jRightWrist_rotx" type="revolute">
        <origin xyz="4.6e-05    -0.23152           0" rpy="0 0 0"/>
        <parent link="RightForeArm"/>
        <child link="RightHand_f1"/>
        <dynamics damping="0.1" friction="0.0"/>
        <limit effort="30" velocity="1.0" lower="-0.872665" upper="1.0472" />
        <axis xyz="1 0 0" />
    </joint>
	<joint name="jRightWrist_rotz" type="revolute">
        <origin xyz="0 0 0" rpy="0 0 0"/>
        <parent link="RightHand_f1"/>
        <child link="RightHand"/>
        <dynamics damping="0.1" friction="0.0"/>
        <limit effort="30" velocity="1.0" lower="-0.523599" upper="0.349066" />
        <axis xyz="0 0 1" />
    </joint>
	<!--Chain from (12) to (15)-->
	<joint name="jLeftC7Shoulder_rotx" type="revolute">
        <origin xyz="0    0.027086    0.066263" rpy="0 0 0"/>
        <parent link="T8"/>
        <child link="LeftShoulder"/>
        <dynamics damping="0.1" friction="0.0"/>
        <limit effort="30" velocity="1.0" lower="-0.0872665" upper="0.785398" />
        <axis xyz="1 0 0" />
    </joint>
	<joint name="jLeftShoulder_rotx" type="revolute">
        <origin xyz="0      0.1369           0" rpy="0 0 0"/>
        <parent link="LeftShoulder"/>
        <child link="LeftUpperArm_f1"/>
        <dynamics damping="0.1" friction="0.0"/>
        <limit effort="30" velocity="1.0" lower="-1.5708" upper="2.35619" />
        <axis xyz="1 0 0" />
    </joint>
	<joint name="jLeftShoulder_roty" type="revolute">
        <origin xyz="0 0 0" rpy="0 0 0"/>
        <parent link="LeftUpperArm_f1"/>
        <child link="LeftUpperArm_f2"/>
        <dynamics damping="0.1" friction="0.0"/>
        <limit effort="30" velocity="1.0" lower="-1.5708" upper="1.5708" />
        <axis xyz="0 1 0" />
    </joint>
    <joint name="jLeftShoulder_rotz" type="revolute">
        <origin xyz="0 0 0" rpy="0 0 0"/>
        <parent link="LeftUpperArm_f2"/>
        <child link="LeftUpperArm"/>
        <dynamics damping="0.1" friction="0.0"/>
        <limit effort="30" velocity="1.0" lower="-3.14159" upper="0.785398" />
        <axis xyz="0 0 1" />
    </joint>
    <joint name="jLeftElbow_roty" type="revolute">
        <origin xyz="0     0.28194           0" rpy="0 0 0"/>
        <parent link="LeftUpperArm"/>
        <child link="LeftForeArm_f1"/>
        <dynamics damping="0.1" friction="0.0"/>
        <limit effort="30" velocity="1.0" lower="-1.5708" upper="1.48353" />
        <axis xyz="0 1 0" />
    </joint>
    <joint name="jLeftElbow_rotz" type="revolute">
        <origin xyz="0 0 0" rpy="0 0 0"/>
        <parent link="LeftForeArm_f1"/>
        <child link="LeftForeArm"/>
        <dynamics damping="0.1" friction="0.0"/>
        <limit effort="30" velocity="1.0" lower="-2.53073" upper="0" />
        <axis xyz="0 0 1" />
    </joint>
	<joint name="jLeftWrist_rotx" type="revolute">
        <origin xyz="4.6e-05     0.23152           0" rpy="0 0 0"/>
        <parent link="LeftForeArm"/>
        <child link="LeftHand_f1"/>
        <dynamics damping="0.1" friction="0.0"/>
        <limit effort="30" velocity="1.0" lower="-1.0472" upper="0.872665" />
        <axis xyz="1 0 0" />
    </joint>
	<joint name="jLeftWrist_rotz" type="revolute">
        <origin xyz="0 0 0" rpy="0 0 0"/>
        <parent link="LeftHand_f1"/>
        <child link="LeftHand"/>
        <dynamics damping="0.1" friction="0.0"/>
        <limit effort="30" velocity="1.0" lower="-0.349066" upper="0.523599" />
        <axis xyz="0 0 1" />
    </joint>
	<!--Chain from (16) to (19)-->
	<joint name="jRightHip_rotx" type="revolute">
        <origin xyz="0.000147    -0.08982    0.001442" rpy="0 0 0"/>
        <parent link="Pelvis"/>
        <child link="RightUpperLeg_f1"/>
        <dynamics damping="0.1" friction="0.0"/>
        <limit effort="30" velocity="1.0" lower="-0.785398" upper="0.523599" />
        <axis xyz="1 0 0" />
    </joint>
	<joint name="jRightHip_roty" type="revolute">
        <origin xyz="0 0 0" rpy="0 0 0"/>
        <parent link="RightUpperLeg_f1"/>
        <child link="RightUpperLeg_f2"/>
        <dynamics damping="0.1" friction="0.0"/>
        <limit effort="30" velocity="1.0" lower="-0.261799" upper="2.0944" />
        <axis xyz="0 1 0" />
    </joint>
    <joint name="jRightHip_rotz" type="revolute">
        <origin xyz="0 0 0" rpy="0 0 0"/>
        <parent link="RightUpperLeg_f2"/>
        <child link="RightUpperLeg"/>
        <dynamics damping="0.1" friction="0.0"/>
        <limit effort="30" velocity="1.0" lower="-0.785398" upper="0.785398" />
        <axis xyz="0 0 1" />
    </joint>
	<joint name="jRightKnee_roty" type="revolute">
        <origin xyz="4.4e-05           0    -0.47078" rpy="0 0 0"/>
        <parent link="RightUpperLeg"/>
        <child link="RightLowerLeg_f1"/>
        <dynamics damping="0.1" friction="0.0"/>
        <limit effort="30" velocity="1.0" lower="0" upper="2.35619" />
        <axis xyz="0 1 0" />
    </joint>
	<joint name="jRightKnee_rotz" type="revolute">
        <origin xyz="0 0 0" rpy="0 0 0"/>
        <parent link="RightLowerLeg_f1"/>
        <child link="RightLowerLeg"/>
        <dynamics damping="0.1" friction="0.0"/>
        <limit effort="30" velocity="1.0" lower="-0.698132" upper="0.523599" />
        <axis xyz="0 0 1" />
    </joint>
	<joint name="jRightAnkle_rotx" type="revolute">
        <origin xyz="0.000156           0    -0.37257" rpy="0 0 0"/>
        <parent link="RightLowerLeg"/>
        <child link="RightFoot_f1"/>
        <dynamics damping="0.1" friction="0.0"/>
        <limit effort="30" velocity="1.0" lower="-0.610865" upper="0.785398" />
        <axis xyz="1 0 0" />
    </joint>
	<joint name="jRightAnkle_roty" type="revolute">
        <origin xyz="0 0 0" rpy="0 0 0"/>
        <parent link="RightFoot_f1"/>
        <child link="RightFoot_f2"/>
        <dynamics damping="0.1" friction="0.0"/>
        <limit effort="30" velocity="1.0" lower="-0.523599" upper="0.872665" />
        <axis xyz="0 1 0" />
    </joint>
    <joint name="jRightAnkle_rotz" type="revolute">
        <origin xyz="0 0 0" rpy="0 0 0"/>
        <parent link="RightFoot_f2"/>
        <child link="RightFoot"/>
        <dynamics damping="0.1" friction="0.0"/>
        <limit effort="30" velocity="1.0" lower="-0.436332" upper="0.872665" />
        <axis xyz="0 0 1" />
    </joint>
	<joint name="jRightBallFoot_roty" type="revolute">
        <origin xyz="0.14858           0   -0.065066" rpy="0 0 0"/>
        <parent link="RightFoot"/>
        <child link="RightToe"/>
        <dynamics damping="0.1" friction="0.0"/>
        <limit effort="30" velocity="1.0" lower="-0.174533" upper="1.5708" />
        <axis xyz="0 1 0" />
    </joint>
	<!--Chain from (20) to (23)-->
	<joint name="jLeftHip_rotx" type="revolute">
        <origin xyz="0.000147     0.08982    0.001442" rpy="0 0 0"/>
        <parent link="Pelvis"/>
        <child link="LeftUpperLeg_f1"/>
        <dynamics damping="0.1" friction="0.0"/>
        <limit effort="30" velocity="1.0" lower="-0.523599" upper="0.785398" />
        <axis xyz="1 0 0" />
    </joint>
	<joint name="jLeftHip_roty" type="revolute">
        <origin xyz="0 0 0" rpy="0 0 0"/>
        <parent link="LeftUpperLeg_f1"/>
        <child link="LeftUpperLeg_f2"/>
        <dynamics damping="0.1" friction="0.0"/>
        <limit effort="30" velocity="1.0" lower="-0.261799" upper="2.0944" />
        <axis xyz="0 1 0" />
    </joint>
    <joint name="jLeftHip_rotz" type="revolute">
        <origin xyz="0 0 0" rpy="0 0 0"/>
        <parent link="LeftUpperLeg_f2"/>
        <child link="LeftUpperLeg"/>
        <dynamics damping="0.1" friction="0.0"/>
        <limit effort="30" velocity="1.0" lower="-0.785398" upper="0.785398" />
        <axis xyz="0 0 1" />
    </joint>
	<joint name="jLeftKnee_roty" type="revolute">
        <origin xyz="4.4e-05           0    -0.47078" rpy="0 0 0"/>
        <parent link="LeftUpperLeg"/>
        <child link="LeftLowerLeg_f1"/>
        <dynamics damping="0.1" friction="0.0"/>
        <limit effort="30" velocity="1.0" lower="0" upper="2.35619" />
        <axis xyz="0 1 0" />
    </joint>
    <joint name="jLeftKnee_rotz" type="revolute">
        <origin xyz="0 0 0" rpy="0 0 0"/>
        <parent link="LeftLowerLeg_f1"/>
        <child link="LeftLowerLeg"/>
        <dynamics damping="0.1" friction="0.0"/>
        <limit effort="30" velocity="1.0" lower="-0.523599" upper="0.698132" />
        <axis xyz="0 0 1" />
    </joint>
	<joint name="jLeftAnkle_rotx" type="revolute">
        <origin xyz="0.000156           0    -0.37257" rpy="0 0 0"/>
        <parent link="LeftLowerLeg"/>
        <child link="LeftFoot_f1"/>
        <dynamics damping="0.1" friction="0.0"/>
        <limit effort="30" velocity="1.0" lower="-0.785398" upper="0.610865" />
        <axis xyz="1 0 0" />
    </joint>
	<joint name="jLeftAnkle_roty" type="revolute">
        <origin xyz="0 0 0" rpy="0 0 0"/>
        <parent link="LeftFoot_f1"/>
        <child link="LeftFoot_f2"/>
        <dynamics damping="0.1" friction="0.0"/>
        <limit effort="30" velocity="1.0" lower="-0.523599" upper="0.872665" />
        <axis xyz="0 1 0" />
    </joint>
    <joint name="jLeftAnkle_rotz" type="revolute">
        <origin xyz="0 0 0" rpy="0 0 0"/>
        <parent link="LeftFoot_f2"/>
        <child link="LeftFoot"/>
        <dynamics damping="0.1" friction="0.0"/>
        <limit effort="30" velocity="1.0" lower="-0.872665" upper="0.436332" />
        <axis xyz="0 0 1" />
    </joint>
	<joint name="jLeftBallFoot_roty" type="revolute">
        <origin xyz="0.14858           0   -0.065066" rpy="0 0 0"/>
        <parent link="LeftFoot"/>
        <child link="LeftToe"/>
        <dynamics damping="0.1" friction="0.0"/>
        <limit effort="30" velocity="1.0" lower="-0.174533" upper="1.5708" />
        <axis xyz="0 1 0" />
    </joint>

	<!-- Sensor  1-->
<sensor name="Pelvis_gyro" type="gyroscope">
<parent link="Pelvis"/>
<origin xyz="-0.062502 -2.1605e-05     0.10679" rpy="0.073038       1.175     -2.9918"/>
</sensor>
<sensor name="Pelvis_accelerometer" type="accelerometer">
<parent link="Pelvis"/>
<origin xyz="-0.062502 -2.1605e-05     0.10679" rpy="0.073038       1.175     -2.9918"/>
</sensor>
<!-- Sensor  2-->
<sensor name="T8_gyro" type="gyroscope">
<parent link="T8"/>
<origin xyz="0.12575 -1.7171e-07    0.069162" rpy="0.05586      1.1455   -0.093381"/>
</sensor>
<sensor name="T8_accelerometer" type="accelerometer">
<parent link="T8"/>
<origin xyz="0.12575 -1.7171e-07    0.069162" rpy="0.05586      1.1455   -0.093381"/>
</sensor>
<!-- Sensor  3-->
<sensor name="Head_gyro" type="gyroscope">
<parent link="Head"/>
<origin xyz="-0.067666 -2.0687e-07    0.074377" rpy="2.0295     0.15178     -1.3955"/>
</sensor>
<sensor name="Head_accelerometer" type="accelerometer">
<parent link="Head"/>
<origin xyz="-0.067666 -2.0687e-07    0.074377" rpy="2.0295     0.15178     -1.3955"/>
</sensor>
<!-- Sensor  4-->
<sensor name="RightShoulder_gyro" type="gyroscope">
<parent link="RightShoulder"/>
<origin xyz="-0.019617   -0.049042    -0.05885" rpy="1.2165    -0.29762     -1.4934"/>
</sensor>
<sensor name="RightShoulder_accelerometer" type="accelerometer">
<parent link="RightShoulder"/>
<origin xyz="-0.019617   -0.049042    -0.05885" rpy="1.2165    -0.29762     -1.4934"/>
</sensor>
<!-- Sensor  5-->
<sensor name="RightUpperArm_gyro" type="gyroscope">
<parent link="RightUpperArm"/>
<origin xyz="-0.01887   -0.094352     0.01887" rpy="0.034231   -0.080938     -1.6293"/>
</sensor>
<sensor name="RightUpperArm_accelerometer" type="accelerometer">
<parent link="RightUpperArm"/>
<origin xyz="-0.01887   -0.094352     0.01887" rpy="0.034231   -0.080938     -1.6293"/>
</sensor>
<!-- Sensor  6-->
<sensor name="RightForeArm_gyro" type="gyroscope">
<parent link="RightForeArm"/>
<origin xyz="0.0017409    -0.18998    0.018975" rpy="-0.64557   -0.032803     -1.2886"/>
</sensor>
<sensor name="RightForeArm_accelerometer" type="accelerometer">
<parent link="RightForeArm"/>
<origin xyz="0.0017409    -0.18998    0.018975" rpy="-0.64557   -0.032803     -1.2886"/>
</sensor>
<!-- Sensor  7-->
<sensor name="RightHand_gyro" type="gyroscope">
<parent link="RightHand"/>
<origin xyz="-3.6244e-08   -0.052468    0.019079" rpy="-0.44135   -0.084915     -1.4651"/>
</sensor>
<sensor name="RightHand_accelerometer" type="accelerometer">
<parent link="RightHand"/>
<origin xyz="-3.6244e-08   -0.052468    0.019079" rpy="-0.44135   -0.084915     -1.4651"/>
</sensor>
<!-- Sensor  8-->
<sensor name="LeftShoulder_gyro" type="gyroscope">
<parent link="LeftShoulder"/>
<origin xyz="-0.019617    0.049042    -0.05885" rpy="-1.1685    -0.30254      1.3128"/>
</sensor>
<sensor name="LeftShoulder_accelerometer" type="accelerometer">
<parent link="LeftShoulder"/>
<origin xyz="-0.019617    0.049042    -0.05885" rpy="-1.1685    -0.30254      1.3128"/>
</sensor>
<!-- Sensor  9-->
<sensor name="LeftUpperArm_gyro" type="gyroscope">
<parent link="LeftUpperArm"/>
<origin xyz="-0.01887    0.094352     0.01887" rpy="-0.21253      -0.119      1.5758"/>
</sensor>
<sensor name="LeftUpperArm_accelerometer" type="accelerometer">
<parent link="LeftUpperArm"/>
<origin xyz="-0.01887    0.094352     0.01887" rpy="-0.21253      -0.119      1.5758"/>
</sensor>
<!-- Sensor  10-->
<sensor name="LeftForeArm_gyro" type="gyroscope">
<parent link="LeftForeArm"/>
<origin xyz="0.001741     0.18998    0.018975" rpy="0.88559   -0.052367      1.2958"/>
</sensor>
<sensor name="LeftForeArm_accelerometer" type="accelerometer">
<parent link="LeftForeArm"/>
<origin xyz="0.001741     0.18998    0.018975" rpy="0.88559   -0.052367      1.2958"/>
</sensor>
<!-- Sensor  11-->
<sensor name="LeftHand_gyro" type="gyroscope">
<parent link="LeftHand"/>
<origin xyz="-2.9489e-08    0.052468    0.019079" rpy="0.63592      0.1106      1.2877"/>
</sensor>
<sensor name="LeftHand_accelerometer" type="accelerometer">
<parent link="LeftHand"/>
<origin xyz="-2.9489e-08    0.052468    0.019079" rpy="0.63592      0.1106      1.2877"/>
</sensor>
<!-- Sensor  12-->
<sensor name="RightUpperLeg_gyro" type="gyroscope">
<parent link="RightUpperLeg"/>
<origin xyz="0.013598   -0.047873    -0.28284" rpy="-2.7346      1.4828      1.7867"/>
</sensor>
<sensor name="RightUpperLeg_accelerometer" type="accelerometer">
<parent link="RightUpperLeg"/>
<origin xyz="0.013598   -0.047873    -0.28284" rpy="-2.7346      1.4828      1.7867"/>
</sensor>
<!-- Sensor  13-->
<sensor name="RightLowerLeg_gyro" type="gyroscope">
<parent link="RightLowerLeg"/>
<origin xyz="0.028446   0.0065111    -0.12238" rpy="-0.72219      1.5504     -1.0017"/>
</sensor>
<sensor name="RightLowerLeg_accelerometer" type="accelerometer">
<parent link="RightLowerLeg"/>
<origin xyz="0.028446   0.0065111    -0.12238" rpy="-0.72219      1.5504     -1.0017"/>
</sensor>
<!-- Sensor  14-->
<sensor name="RightFoot_gyro" type="gyroscope">
<parent link="RightFoot"/>
<origin xyz="0.085688    0.001426   -0.012097" rpy="0.29509     0.47835    -0.44578"/>
</sensor>
<sensor name="RightFoot_accelerometer" type="accelerometer">
<parent link="RightFoot"/>
<origin xyz="0.085688    0.001426   -0.012097" rpy="0.29509     0.47835    -0.44578"/>
</sensor>
<!-- Sensor  15-->
<sensor name="LeftUpperLeg_gyro" type="gyroscope">
<parent link="LeftUpperLeg"/>
<origin xyz="0.013598    0.047874    -0.28284" rpy="2.2144      1.3513     -2.7095"/>
</sensor>
<sensor name="LeftUpperLeg_accelerometer" type="accelerometer">
<parent link="LeftUpperLeg"/>
<origin xyz="0.013598    0.047874    -0.28284" rpy="2.2144      1.3513     -2.7095"/>
</sensor>
<!-- Sensor  16-->
<sensor name="LeftLowerLeg_gyro" type="gyroscope">
<parent link="LeftLowerLeg"/>
<origin xyz="0.028446  -0.0065112    -0.12238" rpy="2.015      1.4009      2.2161"/>
</sensor>
<sensor name="LeftLowerLeg_accelerometer" type="accelerometer">
<parent link="LeftLowerLeg"/>
<origin xyz="0.028446  -0.0065112    -0.12238" rpy="2.015      1.4009      2.2161"/>
</sensor>
<!-- Sensor  17-->
<sensor name="LeftFoot_gyro" type="gyroscope">
<parent link="LeftFoot"/>
<origin xyz="0.085688   -0.001426   -0.012097" rpy="0.12832     0.56786     0.95218"/>
</sensor>
<sensor name="LeftFoot_accelerometer" type="accelerometer">
<parent link="LeftFoot"/>
<origin xyz="0.085688   -0.001426   -0.012097" rpy="0.12832     0.56786     0.95218"/>
</sensor>


</robot>
